Workbook
Name centro: Tabla_Trans_dic_2012.accdb[[#All],[centro]]
Name ind: Tabla_Trans_dic_2012.accdb[[#All],[INDEPENDIENTE]]
Name independiente: Tabla_Trans_dic_2012.accdb[[#All],[INDEPENDIENTE]]
Name mud: Tabla_Trans_dic_2012.accdb[[#All],[MUD]]
Name municipio: Tabla_Trans_dic_2012.accdb[[#All],[municipio]]
Name otro: Tabla_Trans_dic_2012.accdb[[#All],[Otro]]
Name psuv: Tabla_Trans_dic_2012.accdb[[#All],[PSUV]]
Name totalv: Tabla_Trans_dic_2012.accdb[[#All],[totalv]]
Name turno: Tabla_Trans_dic_2012.accdb[[#All],[turno]]

Sheet Entrada
B1: Id | C1: centro | D1: municipio | E1: turno | F1: PSUV | G1: MUD | H1: Otro | I1: INDEPENDIENTE | J1: totalv | K1: usuario
B2: 2 | C2: 11 | D2: 3 | E2: 16 | F2: 2 | G2: 0 | H2: 0 | I2: 0 | J2: 2 | K2: rodolfo
B3: 3 | C3: 9 | D3: 3 | E3: 15 | F3: 22 | G3: 8 | H3: 0 | I3: 0 | J3: 30 | K3: jonathan
B4: 4 | C4: 75 | D4: 37 | E4: 15 | F4: 4 | G4: 3 | H4: 3 | I4: 0 | J4: 10 | K4: jonathan
B5: 5 | C5: 272 | D5: 123 | E5: 1 | F5: 13 | G5: 17 | H5: 0 | I5: 0 | J5: 30 | K5: jonathan
B6: 6 | C6: 273 | D6: 124 | E6: 1 | F6: 19 | G6: 11 | H6: 0 | I6: 0 | J6: 30 | K6: jonathan
B7: 7 | C7: 255 | D7: 116 | E7: 1 | F7: 14 | G7: 2 | H7: 1 | I7: 0 | J7: 17 | K7: jonathan
B8: 14 | C8: 22 | D8: 10 | E8: 2 | F8: 4 | G8: 6 | H8: 0 | I8: 0 | J8: 10 | K8: jonathan
B9: 16 | C9: 3 | D9: 1 | E9: 2 | F9: 9 | G9: 9 | H9: 0 | I9: 0 | J9: 18 | K9: jonathan
B10: 17 | C10: 24 | D10: 12 | E10: 2 | F10: 20 | G10: 4 | H10: 1 | I10: 0 | J10: 25 | K10: jonathan
B11: 19 | C11: 26 | D11: 14 | E11: 2 | F11: 11 | G11: 8 | H11: 4 | I11: 0 | J11: 23 | K11: jonathan
B12: 20 | C12: 7 | D12: 2 | E12: 2 | F12: 15 | G12: 13 | H12: 0 | I12: 0 | J12: 28 | K12: jonathan
B13: 21 | C13: 129 | D13: 57 | E13: 2 | F13: 3 | G13: 16 | H13: 0 | I13: 0 | J13: 19 | K13: jonathan
... B703: 5287 | C703: 198 | D703: 86 | E703: 2 | F703: 6 | G703: 3 | H703: 0 | I703: 0 | J703: 9 | K703: geraldine
A704: * | B704: 5289 | C704: 185 | D704: 81 | E704: 7 | F704: 5 | G704: 10 | H704: 0 | I704: 0 | J704: 15 | K704: gibran
B705: 5291 | C705: 198 | D705: 86 | E705: 3 | F705: 7 | G705: 8 | H705: 1 | I705: 0 | J705: 16 | K705: geraldine
B706: 5292 | C706: 185 | D706: 81 | E706: 8 | F706: 10 | G706: 20 | H706: 0 | I706: 0 | J706: 30 | K706: gibran
B707: 5290 | C707: 42 | D707: 21 | E707: 18 | F707: 11 | G707: 10 | H707: 0 | I707: 0 | J707: 21 | K707: octavio
B708: 776 | C708: 70 | D708: 35 | E708: 4 | F708: 14 | G708: 10 | H708: 6 | I708: 0 | J708: 30 | K708: michelle
B709: 778 | C709: 24 | D709: 12 | E709: 5 | F709: 5 | G709: 7 | H709: 10 | I709: 0 | J709: 22 | K709: gibran
B710: 779 | C710: 4 | D710: 1 | E710: 4 | F710: 3 | G710: 3 | H710: 0 | I710: 0 | J710: 6 | K710: michelle
B711: 780 | C711: 283 | D711: 131 | E711: 5 | F711: 9 | G711: 3 | H711: 0 | I711: 0 | J711: 12 | K711: moises
B712: 781 | C712: 346 | D712: 155 | E712: 4 | F712: 8 | G712: 16 | H712: 0 | I712: 0 | J712: 24 | K712: jonathan
B713: 782 | C713: 33 | D713: 17 | E713: 5 | F713: 7 | G713: 15 | H713: 0 | I713: 0 | J713: 22 | K713: gibran
B714: 783 | C714: 164 | D714: 70 | E714: 5 | F714: 2 | G714: 0 | H714: 0 | I714: 0 | J714: 2 | K714: moises
B715: 785 | C715: 19 | D715: 9 | E715: 5 | F715: 17 | G715: 13 | H715: 0 | I715: 0 | J715: 30 | K715: eugenia
B716: 786 | C716: 78 | D716: 40 | E716: 5 | F716: 4 | G716: 5 | H716: 0 | I716: 0 | J716: 9 | K716: gibran
... B4625: 5122 | C4625: 16 | D4625: 7 | E4625: 7 | F4625: 6 | G4625: 11 | H4625: 0 | I4625: 0 | J4625: 17 | K4625: moises

Sheet Hector
E1: 0.3125 | F1: 0.33333333 | G1: 0.35416667 | H1: 0.375 | I1: 0.39583333 | J1: 0.41666667 | K1: 0.4375 | L1: 0.45833333 | M1: 0.47916667 | N1: 0.5 | O1: 0.52083333 | P1: 0.041666667 | Q1: 0.0625 | R1: 0.083333333 | S1: 0.10416667 | T1: 0.125 | U1: 0.14583333 | V1: 0.16666667
B2: Estado | C2: Candidato | D2: Resultado | E2: 1 | F2: 2 | G2: 3 | H2: 4 | I2: 5 | J2: 6 | K2: 7 | L2: 8 | M2: 9 | N2: 10 | O2: 11 | P2: 12 | Q2: 13 | R2: 14 | S2: 15 | T2: 16 | U2: 17 | V2: 18
B3: Amazonas | C3: Nicia Maldonado | D3: =Alejandro!F5/(Alejandro!$F$5+Alejandro!$F$6+Alejandro!$F$7) -> 0.49724771 | E3: =IF((Alejandro!G$2+Alejandro!G$3+Alejandro!G$4)=0,NA(),Alejandro!G2/(Alejandro!G$2+Alejandro!G$3+Alejandro!G$4)) -> 0.36363636 | F3: =IF((Alejandro!H$2+Alejandro!H$3+Alejandro!H$4)=0,NA(),Alejandro!H2/(Alejandro!H$2+Alejandro!H$3+Alejandro!H$4)) -> 0.44776119 | G3: =IF((Alejandro!I$2+Alejandro!I$3+Alejandro!I$4)=0,NA(),Alejandro!I2/(Alejandro!I$2+Alejandro!I$3+Alejandro!I$4)) -> 0.47154472 | H3: =IF((Alejandro!J$2+Alejandro!J$3+Alejandro!J$4)=0,NA(),Alejandro!J2/(Alejandro!J$2+Alejandro!J$3+Alejandro!J$4)) -> 0.45121951 | I3: =IF((Alejandro!K$2+Alejandro!K$3+Alejandro!K$4)=0,NA(),Alejandro!K2/(Alejandro!K$2+Alejandro!K$3+Alejandro!K$4)) -> 0.45360825 | J3: =IF((Alejandro!L$2+Alejandro!L$3+Alejandro!L$4)=0,NA(),Alejandro!L2/(Alejandro!L$2+Alejandro!L$3+Alejandro!L$4)) -> 0.47945205 | K3: =IF((Alejandro!M$2+Alejandro!M$3+Alejandro!M$4)=0,NA(),Alejandro!M2/(Alejandro!M$2+Alejandro!M$3+Alejandro!M$4)) -> 0.5 | L3: =IF((Alejandro!N$2+Alejandro!N$3+Alejandro!N$4)=0,NA(),Alejandro!N2/(Alejandro!N$2+Alejandro!N$3+Alejandro!N$4)) -> 0.48494983 | ... V3: =IF((Alejandro!X$2+Alejandro!X$3+Alejandro!X$4)=0,NA(),Alejandro!X2/(Alejandro!X$2+Alejandro!X$3+Alejandro!X$4)) -> 0.49724771
C4: Liborio Guarulla | D4: =Alejandro!F6/(Alejandro!$F$5+Alejandro!$F$6+Alejandro!$F$7) -> 0.43669725 | E4: =IF((Alejandro!G$2+Alejandro!G$3+Alejandro!G$4)=0,NA(),Alejandro!G3/(Alejandro!G$2+Alejandro!G$3+Alejandro!G$4)) -> 0.63636364 | F4: =IF((Alejandro!H$2+Alejandro!H$3+Alejandro!H$4)=0,NA(),Alejandro!H3/(Alejandro!H$2+Alejandro!H$3+Alejandro!H$4)) -> 0.55223881 | G4: =IF((Alejandro!I$2+Alejandro!I$3+Alejandro!I$4)=0,NA(),Alejandro!I3/(Alejandro!I$2+Alejandro!I$3+Alejandro!I$4)) -> 0.51219512 | H4: =IF((Alejandro!J$2+Alejandro!J$3+Alejandro!J$4)=0,NA(),Alejandro!J3/(Alejandro!J$2+Alejandro!J$3+Alejandro!J$4)) -> 0.5304878 | I4: =IF((Alejandro!K$2+Alejandro!K$3+Alejandro!K$4)=0,NA(),Alejandro!K3/(Alejandro!K$2+Alejandro!K$3+Alejandro!K$4)) -> 0.52061856 | J4: =IF((Alejandro!L$2+Alejandro!L$3+Alejandro!L$4)=0,NA(),Alejandro!L3/(Alejandro!L$2+Alejandro!L$3+Alejandro!L$4)) -> 0.49315068 | K4: =IF((Alejandro!M$2+Alejandro!M$3+Alejandro!M$4)=0,NA(),Alejandro!M3/(Alejandro!M$2+Alejandro!M$3+Alejandro!M$4)) -> 0.46428571 | L4: =IF((Alejandro!N$2+Alejandro!N$3+Alejandro!N$4)=0,NA(),Alejandro!N3/(Alejandro!N$2+Alejandro!N$3+Alejandro!N$4)) -> 0.46822742 | ... V4: =IF((Alejandro!X$2+Alejandro!X$3+Alejandro!X$4)=0,NA(),Alejandro!X3/(Alejandro!X$2+Alejandro!X$3+Alejandro!X$4)) -> 0.43669725
C5: Otro | D5: =Alejandro!F7/(Alejandro!$F$5+Alejandro!$F$6+Alejandro!$F$7) -> 0.066055046 | E5: =IF((Alejandro!G$2+Alejandro!G$3+Alejandro!G$4)=0,NA(),Alejandro!G4/(Alejandro!G$2+Alejandro!G$3+Alejandro!G$4)) -> 0 | F5: =IF((Alejandro!H$2+Alejandro!H$3+Alejandro!H$4)=0,NA(),Alejandro!H4/(Alejandro!H$2+Alejandro!H$3+Alejandro!H$4)) -> 0 | G5: =IF((Alejandro!I$2+Alejandro!I$3+Alejandro!I$4)=0,NA(),Alejandro!I4/(Alejandro!I$2+Alejandro!I$3+Alejandro!I$4)) -> 0.016260163 | H5: =IF((Alejandro!J$2+Alejandro!J$3+Alejandro!J$4)=0,NA(),Alejandro!J4/(Alejandro!J$2+Alejandro!J$3+Alejandro!J$4)) -> 0.018292683 | I5: =IF((Alejandro!K$2+Alejandro!K$3+Alejandro!K$4)=0,NA(),Alejandro!K4/(Alejandro!K$2+Alejandro!K$3+Alejandro!K$4)) -> 0.025773196 | J5: =IF((Alejandro!L$2+Alejandro!L$3+Alejandro!L$4)=0,NA(),Alejandro!L4/(Alejandro!L$2+Alejandro!L$3+Alejandro!L$4)) -> 0.02739726 | K5: =IF((Alejandro!M$2+Alejandro!M$3+Alejandro!M$4)=0,NA(),Alejandro!M4/(Alejandro!M$2+Alejandro!M$3+Alejandro!M$4)) -> 0.035714286 | L5: =IF((Alejandro!N$2+Alejandro!N$3+Alejandro!N$4)=0,NA(),Alejandro!N4/(Alejandro!N$2+Alejandro!N$3+Alejandro!N$4)) -> 0.046822742 | ... V5: =IF((Alejandro!X$2+Alejandro!X$3+Alejandro!X$4)=0,NA(),Alejandro!X4/(Alejandro!X$2+Alejandro!X$3+Alejandro!X$4)) -> 0.066055046
B6: Anzoategui | C6: Aristóbulo Iztúriz | D6: =Alejandro!F14/(Alejandro!$F$14+Alejandro!$F$15+Alejandro!$F$16) -> 0.58135268 | E6: =IF((Alejandro!G$11+Alejandro!G$12+Alejandro!G$13)=0,NA(),Alejandro!G11/(Alejandro!G$11+Alejandro!G$12+Alejandro!G$13)) -> 0.67034891 | F6: =IF((Alejandro!H$11+Alejandro!H$12+Alejandro!H$13)=0,NA(),Alejandro!H11/(Alejandro!H$11+Alejandro!H$12+Alejandro!H$13)) -> 0.64791346 | G6: =IF((Alejandro!I$11+Alejandro!I$12+Alejandro!I$13)=0,NA(),Alejandro!I11/(Alejandro!I$11+Alejandro!I$12+Alejandro!I$13)) -> 0.63870578 | H6: =IF((Alejandro!J$11+Alejandro!J$12+Alejandro!J$13)=0,NA(),Alejandro!J11/(Alejandro!J$11+Alejandro!J$12+Alejandro!J$13)) -> 0.63091953 | I6: =IF((Alejandro!K$11+Alejandro!K$12+Alejandro!K$13)=0,NA(),Alejandro!K11/(Alejandro!K$11+Alejandro!K$12+Alejandro!K$13)) -> 0.60627904 | J6: =IF((Alejandro!L$11+Alejandro!L$12+Alejandro!L$13)=0,NA(),Alejandro!L11/(Alejandro!L$11+Alejandro!L$12+Alejandro!L$13)) -> 0.58914399 | K6: =IF((Alejandro!M$11+Alejandro!M$12+Alejandro!M$13)=0,NA(),Alejandro!M11/(Alejandro!M$11+Alejandro!M$12+Alejandro!M$13)) -> 0.59217944 | L6: =IF((Alejandro!N$11+Alejandro!N$12+Alejandro!N$13)=0,NA(),Alejandro!N11/(Alejandro!N$11+Alejandro!N$12+Alejandro!N$13)) -> 0.57462447 | ... V6: =IF((Alejandro!X$11+Alejandro!X$12+Alejandro!X$13)=0,NA(),Alejandro!X11/(Alejandro!X$11+Alejandro!X$12+Alejandro!X$13)) -> 0.58135268
C7: Antonio Barreto Sira | D7: =Alejandro!F15/(Alejandro!$F$14+Alejandro!$F$15+Alejandro!$F$16) -> 0.40019382 | E7: =IF((Alejandro!G$11+Alejandro!G$12+Alejandro!G$13)=0,NA(),Alejandro!G12/(Alejandro!G$11+Alejandro!G$12+Alejandro!G$13)) -> 0.29408316 | F7: =IF((Alejandro!H$11+Alejandro!H$12+Alejandro!H$13)=0,NA(),Alejandro!H12/(Alejandro!H$11+Alejandro!H$12+Alejandro!H$13)) -> 0.33628585 | G7: =IF((Alejandro!I$11+Alejandro!I$12+Alejandro!I$13)=0,NA(),Alejandro!I12/(Alejandro!I$11+Alejandro!I$12+Alejandro!I$13)) -> 0.34953845 | H7: =IF((Alejandro!J$11+Alejandro!J$12+Alejandro!J$13)=0,NA(),Alejandro!J12/(Alejandro!J$11+Alejandro!J$12+Alejandro!J$13)) -> 0.35739123 | I7: =IF((Alejandro!K$11+Alejandro!K$12+Alejandro!K$13)=0,NA(),Alejandro!K12/(Alejandro!K$11+Alejandro!K$12+Alejandro!K$13)) -> 0.37473985 | J7: =IF((Alejandro!L$11+Alejandro!L$12+Alejandro!L$13)=0,NA(),Alejandro!L12/(Alejandro!L$11+Alejandro!L$12+Alejandro!L$13)) -> 0.38522128 | K7: =IF((Alejandro!M$11+Alejandro!M$12+Alejandro!M$13)=0,NA(),Alejandro!M12/(Alejandro!M$11+Alejandro!M$12+Alejandro!M$13)) -> 0.38162011 | L7: =IF((Alejandro!N$11+Alejandro!N$12+Alejandro!N$13)=0,NA(),Alejandro!N12/(Alejandro!N$11+Alejandro!N$12+Alejandro!N$13)) -> 0.39895128 | ... V7: =IF((Alejandro!X$11+Alejandro!X$12+Alejandro!X$13)=0,NA(),Alejandro!X12/(Alejandro!X$11+Alejandro!X$12+Alejandro!X$13)) -> 0.40019382
C8: Otro | D8: =Alejandro!F16/(Alejandro!$F$14+Alejandro!$F$15+Alejandro!$F$16) -> 0.018453501 | E8: =IF((Alejandro!G$11+Alejandro!G$12+Alejandro!G$13)=0,NA(),Alejandro!G13/(Alejandro!G$11+Alejandro!G$12+Alejandro!G$13)) -> 0.035567923 | F8: =IF((Alejandro!H$11+Alejandro!H$12+Alejandro!H$13)=0,NA(),Alejandro!H13/(Alejandro!H$11+Alejandro!H$12+Alejandro!H$13)) -> 0.015800689 | G8: =IF((Alejandro!I$11+Alejandro!I$12+Alejandro!I$13)=0,NA(),Alejandro!I13/(Alejandro!I$11+Alejandro!I$12+Alejandro!I$13)) -> 0.011755775 | H8: =IF((Alejandro!J$11+Alejandro!J$12+Alejandro!J$13)=0,NA(),Alejandro!J13/(Alejandro!J$11+Alejandro!J$12+Alejandro!J$13)) -> 0.011689243 | I8: =IF((Alejandro!K$11+Alejandro!K$12+Alejandro!K$13)=0,NA(),Alejandro!K13/(Alejandro!K$11+Alejandro!K$12+Alejandro!K$13)) -> 0.018981114 | J8: =IF((Alejandro!L$11+Alejandro!L$12+Alejandro!L$13)=0,NA(),Alejandro!L13/(Alejandro!L$11+Alejandro!L$12+Alejandro!L$13)) -> 0.025634731 | K8: =IF((Alejandro!M$11+Alejandro!M$12+Alejandro!M$13)=0,NA(),Alejandro!M13/(Alejandro!M$11+Alejandro!M$12+Alejandro!M$13)) -> 0.026200454 | L8: =IF((Alejandro!N$11+Alejandro!N$12+Alejandro!N$13)=0,NA(),Alejandro!N13/(Alejandro!N$11+Alejandro!N$12+Alejandro!N$13)) -> 0.02642425 | ... V8: =IF((Alejandro!X$11+Alejandro!X$12+Alejandro!X$13)=0,NA(),Alejandro!X13/(Alejandro!X$11+Alejandro!X$12+Alejandro!X$13)) -> 0.018453501
B9: Apure | C9: Ramón Carrizález | D9: =Alejandro!F23/(Alejandro!$F$23+Alejandro!$F$24+Alejandro!$F$25) -> 0.49358909 | E9: =IF((Alejandro!G$20+Alejandro!G$21+Alejandro!G$22)=0,NA(),Alejandro!G20/(Alejandro!G$20+Alejandro!G$21+Alejandro!G$22)) -> 0.47596071 | F9: =IF((Alejandro!H$20+Alejandro!H$21+Alejandro!H$22)=0,NA(),Alejandro!H20/(Alejandro!H$20+Alejandro!H$21+Alejandro!H$22)) -> 0.52083169 | G9: =IF((Alejandro!I$20+Alejandro!I$21+Alejandro!I$22)=0,NA(),Alejandro!I20/(Alejandro!I$20+Alejandro!I$21+Alejandro!I$22)) -> 0.49908697 | H9: =IF((Alejandro!J$20+Alejandro!J$21+Alejandro!J$22)=0,NA(),Alejandro!J20/(Alejandro!J$20+Alejandro!J$21+Alejandro!J$22)) -> 0.51526227 | I9: =IF((Alejandro!K$20+Alejandro!K$21+Alejandro!K$22)=0,NA(),Alejandro!K20/(Alejandro!K$20+Alejandro!K$21+Alejandro!K$22)) -> 0.5008291 | J9: =IF((Alejandro!L$20+Alejandro!L$21+Alejandro!L$22)=0,NA(),Alejandro!L20/(Alejandro!L$20+Alejandro!L$21+Alejandro!L$22)) -> 0.47787592 | K9: =IF((Alejandro!M$20+Alejandro!M$21+Alejandro!M$22)=0,NA(),Alejandro!M20/(Alejandro!M$20+Alejandro!M$21+Alejandro!M$22)) -> 0.49384294 | L9: =IF((Alejandro!N$20+Alejandro!N$21+Alejandro!N$22)=0,NA(),Alejandro!N20/(Alejandro!N$20+Alejandro!N$21+Alejandro!N$22)) -> 0.50020855 | ... V9: =IF((Alejandro!X$20+Alejandro!X$21+Alejandro!X$22)=0,NA(),Alejandro!X20/(Alejandro!X$20+Alejandro!X$21+Alejandro!X$22)) -> 0.49358909
C10: Luis Lippa | D10: =Alejandro!F24/(Alejandro!$F$23+Alejandro!$F$24+Alejandro!$F$25) -> 0.29659705 | E10: =IF((Alejandro!G$20+Alejandro!G$21+Alejandro!G$22)=0,NA(),Alejandro!G21/(Alejandro!G$20+Alejandro!G$21+Alejandro!G$22)) -> 0.24404619 | F10: =IF((Alejandro!H$20+Alejandro!H$21+Alejandro!H$22)=0,NA(),Alejandro!H21/(Alejandro!H$20+Alejandro!H$21+Alejandro!H$22)) -> 0.27187112 | G10: =IF((Alejandro!I$20+Alejandro!I$21+Alejandro!I$22)=0,NA(),Alejandro!I21/(Alejandro!I$20+Alejandro!I$21+Alejandro!I$22)) -> 0.28382136 | H10: =IF((Alejandro!J$20+Alejandro!J$21+Alejandro!J$22)=0,NA(),Alejandro!J21/(Alejandro!J$20+Alejandro!J$21+Alejandro!J$22)) -> 0.26822339 | I10: =IF((Alejandro!K$20+Alejandro!K$21+Alejandro!K$22)=0,NA(),Alejandro!K21/(Alejandro!K$20+Alejandro!K$21+Alejandro!K$22)) -> 0.28124564 | J10: =IF((Alejandro!L$20+Alejandro!L$21+Alejandro!L$22)=0,NA(),Alejandro!L21/(Alejandro!L$20+Alejandro!L$21+Alejandro!L$22)) -> 0.32452172 | K10: =IF((Alejandro!M$20+Alejandro!M$21+Alejandro!M$22)=0,NA(),Alejandro!M21/(Alejandro!M$20+Alejandro!M$21+Alejandro!M$22)) -> 0.31949288 | L10: =IF((Alejandro!N$20+Alejandro!N$21+Alejandro!N$22)=0,NA(),Alejandro!N21/(Alejandro!N$20+Alejandro!N$21+Alejandro!N$22)) -> 0.31462782 | ... V10: =IF((Alejandro!X$20+Alejandro!X$21+Alejandro!X$22)=0,NA(),Alejandro!X21/(Alejandro!X$20+Alejandro!X$21+Alejandro!X$22)) -> 0.29659705
C11: Otro | D11: =Alejandro!F25/(Alejandro!$F$23+Alejandro!$F$24+Alejandro!$F$25) -> 0.20981385 | E11: =IF((Alejandro!G$20+Alejandro!G$21+Alejandro!G$22)=0,NA(),Alejandro!G22/(Alejandro!G$20+Alejandro!G$21+Alejandro!G$22)) -> 0.2799931 | F11: =IF((Alejandro!H$20+Alejandro!H$21+Alejandro!H$22)=0,NA(),Alejandro!H22/(Alejandro!H$20+Alejandro!H$21+Alejandro!H$22)) -> 0.20729719 | G11: =IF((Alejandro!I$20+Alejandro!I$21+Alejandro!I$22)=0,NA(),Alejandro!I22/(Alejandro!I$20+Alejandro!I$21+Alejandro!I$22)) -> 0.21709166 | H11: =IF((Alejandro!J$20+Alejandro!J$21+Alejandro!J$22)=0,NA(),Alejandro!J22/(Alejandro!J$20+Alejandro!J$21+Alejandro!J$22)) -> 0.21651434 | I11: =IF((Alejandro!K$20+Alejandro!K$21+Alejandro!K$22)=0,NA(),Alejandro!K22/(Alejandro!K$20+Alejandro!K$21+Alejandro!K$22)) -> 0.21792526 | J11: =IF((Alejandro!L$20+Alejandro!L$21+Alejandro!L$22)=0,NA(),Alejandro!L22/(Alejandro!L$20+Alejandro!L$21+Alejandro!L$22)) -> 0.19760236 | K11: =IF((Alejandro!M$20+Alejandro!M$21+Alejandro!M$22)=0,NA(),Alejandro!M22/(Alejandro!M$20+Alejandro!M$21+Alejandro!M$22)) -> 0.18666418 | L11: =IF((Alejandro!N$20+Alejandro!N$21+Alejandro!N$22)=0,NA(),Alejandro!N22/(Alejandro!N$20+Alejandro!N$21+Alejandro!N$22)) -> 0.18516363 | ... V11: =IF((Alejandro!X$20+Alejandro!X$21+Alejandro!X$22)=0,NA(),Alejandro!X22/(Alejandro!X$20+Alejandro!X$21+Alejandro!X$22)) -> 0.20981385
B12: Aragua | C12: Tareck El Aissami | D12: =Alejandro!F32/(Alejandro!$F$32+Alejandro!$F$33+Alejandro!$F$34) -> 0.5310806 | E12: =IF((Alejandro!G$29+Alejandro!G$30+Alejandro!G$31)=0,NA(),Alejandro!G29/(Alejandro!G$29+Alejandro!G$30+Alejandro!G$31)) -> 0.62301981 | F12: =IF((Alejandro!H$29+Alejandro!H$30+Alejandro!H$31)=0,NA(),Alejandro!H29/(Alejandro!H$29+Alejandro!H$30+Alejandro!H$31)) -> 0.56606447 | G12: =IF((Alejandro!I$29+Alejandro!I$30+Alejandro!I$31)=0,NA(),Alejandro!I29/(Alejandro!I$29+Alejandro!I$30+Alejandro!I$31)) -> 0.52816493 | H12: =IF((Alejandro!J$29+Alejandro!J$30+Alejandro!J$31)=0,NA(),Alejandro!J29/(Alejandro!J$29+Alejandro!J$30+Alejandro!J$31)) -> 0.52012884 | I12: =IF((Alejandro!K$29+Alejandro!K$30+Alejandro!K$31)=0,NA(),Alejandro!K29/(Alejandro!K$29+Alejandro!K$30+Alejandro!K$31)) -> 0.51242826 | J12: =IF((Alejandro!L$29+Alejandro!L$30+Alejandro!L$31)=0,NA(),Alejandro!L29/(Alejandro!L$29+Alejandro!L$30+Alejandro!L$31)) -> 0.54279934 | K12: =IF((Alejandro!M$29+Alejandro!M$30+Alejandro!M$31)=0,NA(),Alejandro!M29/(Alejandro!M$29+Alejandro!M$30+Alejandro!M$31)) -> 0.52729989 | L12: =IF((Alejandro!N$29+Alejandro!N$30+Alejandro!N$31)=0,NA(),Alejandro!N29/(Alejandro!N$29+Alejandro!N$30+Alejandro!N$31)) -> 0.53658138 | ... V12: =IF((Alejandro!X$29+Alejandro!X$30+Alejandro!X$31)=0,NA(),Alejandro!X29/(Alejandro!X$29+Alejandro!X$30+Alejandro!X$31)) -> 0.5310806
C13: Richard Mardo | D13: =Alejandro!F33/(Alejandro!$F$32+Alejandro!$F$33+Alejandro!$F$34) -> 0.4539795 | E13: =IF((Alejandro!G$29+Alejandro!G$30+Alejandro!G$31)=0,NA(),Alejandro!G30/(Alejandro!G$29+Alejandro!G$30+Alejandro!G$31)) -> 0.36500738 | F13: =IF((Alejandro!H$29+Alejandro!H$30+Alejandro!H$31)=0,NA(),Alejandro!H30/(Alejandro!H$29+Alejandro!H$30+Alejandro!H$31)) -> 0.39544573 | G13: =IF((Alejandro!I$29+Alejandro!I$30+Alejandro!I$31)=0,NA(),Alejandro!I30/(Alejandro!I$29+Alejandro!I$30+Alejandro!I$31)) -> 0.44997188 | H13: =IF((Alejandro!J$29+Alejandro!J$30+Alejandro!J$31)=0,NA(),Alejandro!J30/(Alejandro!J$29+Alejandro!J$30+Alejandro!J$31)) -> 0.45777698 | I13: =IF((Alejandro!K$29+Alejandro!K$30+Alejandro!K$31)=0,NA(),Alejandro!K30/(Alejandro!K$29+Alejandro!K$30+Alejandro!K$31)) -> 0.47054416 | J13: =IF((Alejandro!L$29+Alejandro!L$30+Alejandro!L$31)=0,NA(),Alejandro!L30/(Alejandro!L$29+Alejandro!L$30+Alejandro!L$31)) -> 0.44234634 | K13: =IF((Alejandro!M$29+Alejandro!M$30+Alejandro!M$31)=0,NA(),Alejandro!M30/(Alejandro!M$29+Alejandro!M$30+Alejandro!M$31)) -> 0.45705192 | L13: =IF((Alejandro!N$29+Alejandro!N$30+Alejandro!N$31)=0,NA(),Alejandro!N30/(Alejandro!N$29+Alejandro!N$30+Alejandro!N$31)) -> 0.44771578 | ... V13: =IF((Alejandro!X$29+Alejandro!X$30+Alejandro!X$31)=0,NA(),Alejandro!X30/(Alejandro!X$29+Alejandro!X$30+Alejandro!X$31)) -> 0.4539795
C14: Otro | D14: =Alejandro!F34/(Alejandro!$F$32+Alejandro!$F$33+Alejandro!$F$34) -> 0.014939904 | E14: =IF((Alejandro!G$29+Alejandro!G$30+Alejandro!G$31)=0,NA(),Alejandro!G31/(Alejandro!G$29+Alejandro!G$30+Alejandro!G$31)) -> 0.011972808 | F14: =IF((Alejandro!H$29+Alejandro!H$30+Alejandro!H$31)=0,NA(),Alejandro!H31/(Alejandro!H$29+Alejandro!H$30+Alejandro!H$31)) -> 0.038489797 | G14: =IF((Alejandro!I$29+Alejandro!I$30+Alejandro!I$31)=0,NA(),Alejandro!I31/(Alejandro!I$29+Alejandro!I$30+Alejandro!I$31)) -> 0.021863193 | H14: =IF((Alejandro!J$29+Alejandro!J$30+Alejandro!J$31)=0,NA(),Alejandro!J31/(Alejandro!J$29+Alejandro!J$30+Alejandro!J$31)) -> 0.022094184 | I14: =IF((Alejandro!K$29+Alejandro!K$30+Alejandro!K$31)=0,NA(),Alejandro!K31/(Alejandro!K$29+Alejandro!K$30+Alejandro!K$31)) -> 0.017027579 | J14: =IF((Alejandro!L$29+Alejandro!L$30+Alejandro!L$31)=0,NA(),Alejandro!L31/(Alejandro!L$29+Alejandro!L$30+Alejandro!L$31)) -> 0.014854321 | K14: =IF((Alejandro!M$29+Alejandro!M$30+Alejandro!M$31)=0,NA(),Alejandro!M31/(Alejandro!M$29+Alejandro!M$30+Alejandro!M$31)) -> 0.015648189 | L14: =IF((Alejandro!N$29+Alejandro!N$30+Alejandro!N$31)=0,NA(),Alejandro!N31/(Alejandro!N$29+Alejandro!N$30+Alejandro!N$31)) -> 0.015702838 | ... V14: =IF((Alejandro!X$29+Alejandro!X$30+Alejandro!X$31)=0,NA(),Alejandro!X31/(Alejandro!X$29+Alejandro!X$30+Alejandro!X$31)) -> 0.014939904
B15: Barinas | C15: Adán Chávez | D15: =Alejandro!F41/(Alejandro!$F$41+Alejandro!$F$42+Alejandro!$F$43) -> 0.40061443 | E15: =IF((Alejandro!G$38+Alejandro!G$39+Alejandro!G$40)=0,NA(),Alejandro!G38/(Alejandro!G$38+Alejandro!G$39+Alejandro!G$40)) -> 0.37080697 | F15: =IF((Alejandro!H$38+Alejandro!H$39+Alejandro!H$40)=0,NA(),Alejandro!H38/(Alejandro!H$38+Alejandro!H$39+Alejandro!H$40)) -> 0.42677523 | G15: =IF((Alejandro!I$38+Alejandro!I$39+Alejandro!I$40)=0,NA(),Alejandro!I38/(Alejandro!I$38+Alejandro!I$39+Alejandro!I$40)) -> 0.39709166 | H15: =IF((Alejandro!J$38+Alejandro!J$39+Alejandro!J$40)=0,NA(),Alejandro!J38/(Alejandro!J$38+Alejandro!J$39+Alejandro!J$40)) -> 0.42586522 | I15: =IF((Alejandro!K$38+Alejandro!K$39+Alejandro!K$40)=0,NA(),Alejandro!K38/(Alejandro!K$38+Alejandro!K$39+Alejandro!K$40)) -> 0.44496301 | J15: =IF((Alejandro!L$38+Alejandro!L$39+Alejandro!L$40)=0,NA(),Alejandro!L38/(Alejandro!L$38+Alejandro!L$39+Alejandro!L$40)) -> 0.44994503 | K15: =IF((Alejandro!M$38+Alejandro!M$39+Alejandro!M$40)=0,NA(),Alejandro!M38/(Alejandro!M$38+Alejandro!M$39+Alejandro!M$40)) -> 0.45051459 | L15: =IF((Alejandro!N$38+Alejandro!N$39+Alejandro!N$40)=0,NA(),Alejandro!N38/(Alejandro!N$38+Alejandro!N$39+Alejandro!N$40)) -> 0.42825042 | ... V15: =IF((Alejandro!X$38+Alejandro!X$39+Alejandro!X$40)=0,NA(),Alejandro!X38/(Alejandro!X$38+Alejandro!X$39+Alejandro!X$40)) -> 0.38312331
C16: Julio Cesar Reyes | D16: =Alejandro!F42/(Alejandro!$F$41+Alejandro!$F$42+Alejandro!$F$43) -> 0.5730002 | E16: =IF((Alejandro!G$38+Alejandro!G$39+Alejandro!G$40)=0,NA(),Alejandro!G39/(Alejandro!G$38+Alejandro!G$39+Alejandro!G$40)) -> 0.62919303 | F16: =IF((Alejandro!H$38+Alejandro!H$39+Alejandro!H$40)=0,NA(),Alejandro!H39/(Alejandro!H$38+Alejandro!H$39+Alejandro!H$40)) -> 0.56975528 | G16: =IF((Alejandro!I$38+Alejandro!I$39+Alejandro!I$40)=0,NA(),Alejandro!I39/(Alejandro!I$38+Alejandro!I$39+Alejandro!I$40)) -> 0.56946888 | H16: =IF((Alejandro!J$38+Alejandro!J$39+Alejandro!J$40)=0,NA(),Alejandro!J39/(Alejandro!J$38+Alejandro!J$39+Alejandro!J$40)) -> 0.53999687 | I16: =IF((Alejandro!K$38+Alejandro!K$39+Alejandro!K$40)=0,NA(),Alejandro!K39/(Alejandro!K$38+Alejandro!K$39+Alejandro!K$40)) -> 0.52807346 | J16: =IF((Alejandro!L$38+Alejandro!L$39+Alejandro!L$40)=0,NA(),Alejandro!L39/(Alejandro!L$38+Alejandro!L$39+Alejandro!L$40)) -> 0.52656295 | K16: =IF((Alejandro!M$38+Alejandro!M$39+Alejandro!M$40)=0,NA(),Alejandro!M39/(Alejandro!M$38+Alejandro!M$39+Alejandro!M$40)) -> 0.52888039 | L16: =IF((Alejandro!N$38+Alejandro!N$39+Alejandro!N$40)=0,NA(),Alejandro!N39/(Alejandro!N$38+Alejandro!N$39+Alejandro!N$40)) -> 0.5419966 | ... V16: =IF((Alejandro!X$38+Alejandro!X$39+Alejandro!X$40)=0,NA(),Alejandro!X39/(Alejandro!X$38+Alejandro!X$39+Alejandro!X$40)) -> 0.59289618
C17: Otro | D17: =Alejandro!F43/(Alejandro!$F$41+Alejandro!$F$42+Alejandro!$F$43) -> 0.02638538 | E17: =IF((Alejandro!G$38+Alejandro!G$39+Alejandro!G$40)=0,NA(),Alejandro!G40/(Alejandro!G$38+Alejandro!G$39+Alejandro!G$40)) -> 0 | F17: =IF((Alejandro!H$38+Alejandro!H$39+Alejandro!H$40)=0,NA(),Alejandro!H40/(Alejandro!H$38+Alejandro!H$39+Alejandro!H$40)) -> 0.0034694881 | G17: =IF((Alejandro!I$38+Alejandro!I$39+Alejandro!I$40)=0,NA(),Alejandro!I40/(Alejandro!I$38+Alejandro!I$39+Alejandro!I$40)) -> 0.033439457 | H17: =IF((Alejandro!J$38+Alejandro!J$39+Alejandro!J$40)=0,NA(),Alejandro!J40/(Alejandro!J$38+Alejandro!J$39+Alejandro!J$40)) -> 0.034137914 | I17: =IF((Alejandro!K$38+Alejandro!K$39+Alejandro!K$40)=0,NA(),Alejandro!K40/(Alejandro!K$38+Alejandro!K$39+Alejandro!K$40)) -> 0.026963531 | J17: =IF((Alejandro!L$38+Alejandro!L$39+Alejandro!L$40)=0,NA(),Alejandro!L40/(Alejandro!L$38+Alejandro!L$39+Alejandro!L$40)) -> 0.023492025 | K17: =IF((Alejandro!M$38+Alejandro!M$39+Alejandro!M$40)=0,NA(),Alejandro!M40/(Alejandro!M$38+Alejandro!M$39+Alejandro!M$40)) -> 0.020605028 | L17: =IF((Alejandro!N$38+Alejandro!N$39+Alejandro!N$40)=0,NA(),Alejandro!N40/(Alejandro!N$38+Alejandro!N$39+Alejandro!N$40)) -> 0.029752974 | ... V17: =IF((Alejandro!X$38+Alejandro!X$39+Alejandro!X$40)=0,NA(),Alejandro!X40/(Alejandro!X$38+Alejandro!X$39+Alejandro!X$40)) -> 0.023980514
B18: Bolivar | C18: Francisco Rangel Gómez | D18: =Alejandro!F50/(Alejandro!$F$50+Alejandro!$F$51+Alejandro!$F$52) -> 0.39132608 | E18: =IF((Alejandro!G$47+Alejandro!G$48+Alejandro!G$49)=0,NA(),Alejandro!G47/(Alejandro!G$47+Alejandro!G$48+Alejandro!G$49)) -> 0.38115818 | F18: =IF((Alejandro!H$47+Alejandro!H$48+Alejandro!H$49)=0,NA(),Alejandro!H47/(Alejandro!H$47+Alejandro!H$48+Alejandro!H$49)) -> 0.40508076 | G18: =IF((Alejandro!I$47+Alejandro!I$48+Alejandro!I$49)=0,NA(),Alejandro!I47/(Alejandro!I$47+Alejandro!I$48+Alejandro!I$49)) -> 0.41603343 | H18: =IF((Alejandro!J$47+Alejandro!J$48+Alejandro!J$49)=0,NA(),Alejandro!J47/(Alejandro!J$47+Alejandro!J$48+Alejandro!J$49)) -> 0.42883812 | I18: =IF((Alejandro!K$47+Alejandro!K$48+Alejandro!K$49)=0,NA(),Alejandro!K47/(Alejandro!K$47+Alejandro!K$48+Alejandro!K$49)) -> 0.4266802 | J18: =IF((Alejandro!L$47+Alejandro!L$48+Alejandro!L$49)=0,NA(),Alejandro!L47/(Alejandro!L$47+Alejandro!L$48+Alejandro!L$49)) -> 0.4136483 | K18: =IF((Alejandro!M$47+Alejandro!M$48+Alejandro!M$49)=0,NA(),Alejandro!M47/(Alejandro!M$47+Alejandro!M$48+Alejandro!M$49)) -> 0.41284639 | L18: =IF((Alejandro!N$47+Alejandro!N$48+Alejandro!N$49)=0,NA(),Alejandro!N47/(Alejandro!N$47+Alejandro!N$48+Alejandro!N$49)) -> 0.40992448 | ... V18: =IF((Alejandro!X$47+Alejandro!X$48+Alejandro!X$49)=0,NA(),Alejandro!X47/(Alejandro!X$47+Alejandro!X$48+Alejandro!X$49)) -> 0.39132608
C19: Andrés Velásquez | D19: =Alejandro!F51/(Alejandro!$F$50+Alejandro!$F$51+Alejandro!$F$52) -> 0.41561256 | E19: =IF((Alejandro!G$47+Alejandro!G$48+Alejandro!G$49)=0,NA(),Alejandro!G48/(Alejandro!G$47+Alejandro!G$48+Alejandro!G$49)) -> 0.5007254 | F19: =IF((Alejandro!H$47+Alejandro!H$48+Alejandro!H$49)=0,NA(),Alejandro!H48/(Alejandro!H$47+Alejandro!H$48+Alejandro!H$49)) -> 0.44840863 | G19: =IF((Alejandro!I$47+Alejandro!I$48+Alejandro!I$49)=0,NA(),Alejandro!I48/(Alejandro!I$47+Alejandro!I$48+Alejandro!I$49)) -> 0.4440799 | H19: =IF((Alejandro!J$47+Alejandro!J$48+Alejandro!J$49)=0,NA(),Alejandro!J48/(Alejandro!J$47+Alejandro!J$48+Alejandro!J$49)) -> 0.43033311 | I19: =IF((Alejandro!K$47+Alejandro!K$48+Alejandro!K$49)=0,NA(),Alejandro!K48/(Alejandro!K$47+Alejandro!K$48+Alejandro!K$49)) -> 0.43009975 | J19: =IF((Alejandro!L$47+Alejandro!L$48+Alejandro!L$49)=0,NA(),Alejandro!L48/(Alejandro!L$47+Alejandro!L$48+Alejandro!L$49)) -> 0.43634741 | K19: =IF((Alejandro!M$47+Alejandro!M$48+Alejandro!M$49)=0,NA(),Alejandro!M48/(Alejandro!M$47+Alejandro!M$48+Alejandro!M$49)) -> 0.43345699 | L19: =IF((Alejandro!N$47+Alejandro!N$48+Alejandro!N$49)=0,NA(),Alejandro!N48/(Alejandro!N$47+Alejandro!N$48+Alejandro!N$49)) -> 0.43147368 | ... V19: =IF((Alejandro!X$47+Alejandro!X$48+Alejandro!X$49)=0,NA(),Alejandro!X48/(Alejandro!X$47+Alejandro!X$48+Alejandro!X$49)) -> 0.41561256
C20: Otro | D20: =Alejandro!F52/(Alejandro!$F$50+Alejandro!$F$51+Alejandro!$F$52) -> 0.19306136 | E20: =IF((Alejandro!G$47+Alejandro!G$48+Alejandro!G$49)=0,NA(),Alejandro!G49/(Alejandro!G$47+Alejandro!G$48+Alejandro!G$49)) -> 0.11811642 | F20: =IF((Alejandro!H$47+Alejandro!H$48+Alejandro!H$49)=0,NA(),Alejandro!H49/(Alejandro!H$47+Alejandro!H$48+Alejandro!H$49)) -> 0.14651061 | G20: =IF((Alejandro!I$47+Alejandro!I$48+Alejandro!I$49)=0,NA(),Alejandro!I49/(Alejandro!I$47+Alejandro!I$48+Alejandro!I$49)) -> 0.13988667 | H20: =IF((Alejandro!J$47+Alejandro!J$48+Alejandro!J$49)=0,NA(),Alejandro!J49/(Alejandro!J$47+Alejandro!J$48+Alejandro!J$49)) -> 0.14082877 | I20: =IF((Alejandro!K$47+Alejandro!K$48+Alejandro!K$49)=0,NA(),Alejandro!K49/(Alejandro!K$47+Alejandro!K$48+Alejandro!K$49)) -> 0.14322005 | J20: =IF((Alejandro!L$47+Alejandro!L$48+Alejandro!L$49)=0,NA(),Alejandro!L49/(Alejandro!L$47+Alejandro!L$48+Alejandro!L$49)) -> 0.15000429 | K20: =IF((Alejandro!M$47+Alejandro!M$48+Alejandro!M$49)=0,NA(),Alejandro!M49/(Alejandro!M$47+Alejandro!M$48+Alejandro!M$49)) -> 0.15369662 | L20: =IF((Alejandro!N$47+Alejandro!N$48+Alejandro!N$49)=0,NA(),Alejandro!N49/(Alejandro!N$47+Alejandro!N$48+Alejandro!N$49)) -> 0.15860184 | ... V20: =IF((Alejandro!X$47+Alejandro!X$48+Alejandro!X$49)=0,NA(),Alejandro!X49/(Alejandro!X$47+Alejandro!X$48+Alejandro!X$49)) -> 0.19306136
B21: Carabobo | C21: Francisco Ameliach | D21: =Alejandro!F59/(Alejandro!$F$59+Alejandro!$F$60+Alejandro!$F$61) -> 0.53475121 | E21: =IF((Alejandro!G$56+Alejandro!G$57+Alejandro!G$58)=0,NA(),Alejandro!G56/(Alejandro!G$56+Alejandro!G$57+Alejandro!G$58)) -> 0.57646834 | F21: =IF((Alejandro!H$56+Alejandro!H$57+Alejandro!H$58)=0,NA(),Alejandro!H56/(Alejandro!H$56+Alejandro!H$57+Alejandro!H$58)) -> 0.53468455 | G21: =IF((Alejandro!I$56+Alejandro!I$57+Alejandro!I$58)=0,NA(),Alejandro!I56/(Alejandro!I$56+Alejandro!I$57+Alejandro!I$58)) -> 0.53915457 | H21: =IF((Alejandro!J$56+Alejandro!J$57+Alejandro!J$58)=0,NA(),Alejandro!J56/(Alejandro!J$56+Alejandro!J$57+Alejandro!J$58)) -> 0.53615587 | I21: =IF((Alejandro!K$56+Alejandro!K$57+Alejandro!K$58)=0,NA(),Alejandro!K56/(Alejandro!K$56+Alejandro!K$57+Alejandro!K$58)) -> 0.55342673 | J21: =IF((Alejandro!L$56+Alejandro!L$57+Alejandro!L$58)=0,NA(),Alejandro!L56/(Alejandro!L$56+Alejandro!L$57+Alejandro!L$58)) -> 0.5622577 | K21: =IF((Alejandro!M$56+Alejandro!M$57+Alejandro!M$58)=0,NA(),Alejandro!M56/(Alejandro!M$56+Alejandro!M$57+Alejandro!M$58)) -> 0.55671099 | L21: =IF((Alejandro!N$56+Alejandro!N$57+Alejandro!N$58)=0,NA(),Alejandro!N56/(Alejandro!N$56+Alejandro!N$57+Alejandro!N$58)) -> 0.54851139 | ... V21: =IF((Alejandro!X$56+Alejandro!X$57+Alejandro!X$58)=0,NA(),Alejandro!X56/(Alejandro!X$56+Alejandro!X$57+Alejandro!X$58)) -> 0.53475121
C22: Henrique Salas Feo | D22: =Alejandro!F60/(Alejandro!$F$59+Alejandro!$F$60+Alejandro!$F$61) -> 0.42214298 | E22: =IF((Alejandro!G$56+Alejandro!G$57+Alejandro!G$58)=0,NA(),Alejandro!G57/(Alejandro!G$56+Alejandro!G$57+Alejandro!G$58)) -> 0.37097224 | F22: =IF((Alejandro!H$56+Alejandro!H$57+Alejandro!H$58)=0,NA(),Alejandro!H57/(Alejandro!H$56+Alejandro!H$57+Alejandro!H$58)) -> 0.41311946 | G22: =IF((Alejandro!I$56+Alejandro!I$57+Alejandro!I$58)=0,NA(),Alejandro!I57/(Alejandro!I$56+Alejandro!I$57+Alejandro!I$58)) -> 0.40525387 | H22: =IF((Alejandro!J$56+Alejandro!J$57+Alejandro!J$58)=0,NA(),Alejandro!J57/(Alejandro!J$56+Alejandro!J$57+Alejandro!J$58)) -> 0.39914787 | I22: =IF((Alejandro!K$56+Alejandro!K$57+Alejandro!K$58)=0,NA(),Alejandro!K57/(Alejandro!K$56+Alejandro!K$57+Alejandro!K$58)) -> 0.39167733 | J22: =IF((Alejandro!L$56+Alejandro!L$57+Alejandro!L$58)=0,NA(),Alejandro!L57/(Alejandro!L$56+Alejandro!L$57+Alejandro!L$58)) -> 0.38514065 | K22: =IF((Alejandro!M$56+Alejandro!M$57+Alejandro!M$58)=0,NA(),Alejandro!M57/(Alejandro!M$56+Alejandro!M$57+Alejandro!M$58)) -> 0.39404314 | L22: =IF((Alejandro!N$56+Alejandro!N$57+Alejandro!N$58)=0,NA(),Alejandro!N57/(Alejandro!N$56+Alejandro!N$57+Alejandro!N$58)) -> 0.40461111 | ... V22: =IF((Alejandro!X$56+Alejandro!X$57+Alejandro!X$58)=0,NA(),Alejandro!X57/(Alejandro!X$56+Alejandro!X$57+Alejandro!X$58)) -> 0.42214298
C23: Otro | D23: =Alejandro!F61/(Alejandro!$F$59+Alejandro!$F$60+Alejandro!$F$61) -> 0.043105809 | E23: =IF((Alejandro!G$56+Alejandro!G$57+Alejandro!G$58)=0,NA(),Alejandro!G58/(Alejandro!G$56+Alejandro!G$57+Alejandro!G$58)) -> 0.052559417 | F23: =IF((Alejandro!H$56+Alejandro!H$57+Alejandro!H$58)=0,NA(),Alejandro!H58/(Alejandro!H$56+Alejandro!H$57+Alejandro!H$58)) -> 0.052195994 | G23: =IF((Alejandro!I$56+Alejandro!I$57+Alejandro!I$58)=0,NA(),Alejandro!I58/(Alejandro!I$56+Alejandro!I$57+Alejandro!I$58)) -> 0.055591559 | H23: =IF((Alejandro!J$56+Alejandro!J$57+Alejandro!J$58)=0,NA(),Alejandro!J58/(Alejandro!J$56+Alejandro!J$57+Alejandro!J$58)) -> 0.06469626 | I23: =IF((Alejandro!K$56+Alejandro!K$57+Alejandro!K$58)=0,NA(),Alejandro!K58/(Alejandro!K$56+Alejandro!K$57+Alejandro!K$58)) -> 0.054895933 | J23: =IF((Alejandro!L$56+Alejandro!L$57+Alejandro!L$58)=0,NA(),Alejandro!L58/(Alejandro!L$56+Alejandro!L$57+Alejandro!L$58)) -> 0.052601652 | K23: =IF((Alejandro!M$56+Alejandro!M$57+Alejandro!M$58)=0,NA(),Alejandro!M58/(Alejandro!M$56+Alejandro!M$57+Alejandro!M$58)) -> 0.049245862 | L23: =IF((Alejandro!N$56+Alejandro!N$57+Alejandro!N$58)=0,NA(),Alejandro!N58/(Alejandro!N$56+Alejandro!N$57+Alejandro!N$58)) -> 0.046877495 | ... V23: =IF((Alejandro!X$56+Alejandro!X$57+Alejandro!X$58)=0,NA(),Alejandro!X58/(Alejandro!X$56+Alejandro!X$57+Alejandro!X$58)) -> 0.043105809
B24: Cojedes | C24: Érika Farías | D24: =Alejandro!F68/(Alejandro!$F$68+Alejandro!$F$69+Alejandro!$F$70) -> 0.42889252 | E24: =IF((Alejandro!G$65+Alejandro!G$66+Alejandro!G$67)=0,NA(),Alejandro!G65/(Alejandro!G$65+Alejandro!G$66+Alejandro!G$67)) -> 0.4 | F24: =IF((Alejandro!H$65+Alejandro!H$66+Alejandro!H$67)=0,NA(),Alejandro!H65/(Alejandro!H$65+Alejandro!H$66+Alejandro!H$67)) -> 0.32222222 | G24: =IF((Alejandro!I$65+Alejandro!I$66+Alejandro!I$67)=0,NA(),Alejandro!I65/(Alejandro!I$65+Alejandro!I$66+Alejandro!I$67)) -> 0.36844248 | H24: =IF((Alejandro!J$65+Alejandro!J$66+Alejandro!J$67)=0,NA(),Alejandro!J65/(Alejandro!J$65+Alejandro!J$66+Alejandro!J$67)) -> 0.39756083 | I24: =IF((Alejandro!K$65+Alejandro!K$66+Alejandro!K$67)=0,NA(),Alejandro!K65/(Alejandro!K$65+Alejandro!K$66+Alejandro!K$67)) -> 0.41270999 | J24: =IF((Alejandro!L$65+Alejandro!L$66+Alejandro!L$67)=0,NA(),Alejandro!L65/(Alejandro!L$65+Alejandro!L$66+Alejandro!L$67)) -> 0.40895648 | K24: =IF((Alejandro!M$65+Alejandro!M$66+Alejandro!M$67)=0,NA(),Alejandro!M65/(Alejandro!M$65+Alejandro!M$66+Alejandro!M$67)) -> 0.43798375 | L24: =IF((Alejandro!N$65+Alejandro!N$66+Alejandro!N$67)=0,NA(),Alejandro!N65/(Alejandro!N$65+Alejandro!N$66+Alejandro!N$67)) -> 0.44082513 | ... V24: =IF((Alejandro!X$65+Alejandro!X$66+Alejandro!X$67)=0,NA(),Alejandro!X65/(Alejandro!X$65+Alejandro!X$66+Alejandro!X$67)) -> 0.42889252
C25: Alberto Galindez | D25: =Alejandro!F69/(Alejandro!$F$68+Alejandro!$F$69+Alejandro!$F$70) -> 0.44392265 | E25: =IF((Alejandro!G$65+Alejandro!G$66+Alejandro!G$67)=0,NA(),Alejandro!G66/(Alejandro!G$65+Alejandro!G$66+Alejandro!G$67)) -> 0.41666667 | F25: =IF((Alejandro!H$65+Alejandro!H$66+Alejandro!H$67)=0,NA(),Alejandro!H66/(Alejandro!H$65+Alejandro!H$66+Alejandro!H$67)) -> 0.34444444 | G25: =IF((Alejandro!I$65+Alejandro!I$66+Alejandro!I$67)=0,NA(),Alejandro!I66/(Alejandro!I$65+Alejandro!I$66+Alejandro!I$67)) -> 0.35223646 | H25: =IF((Alejandro!J$65+Alejandro!J$66+Alejandro!J$67)=0,NA(),Alejandro!J66/(Alejandro!J$65+Alejandro!J$66+Alejandro!J$67)) -> 0.34757604 | I25: =IF((Alejandro!K$65+Alejandro!K$66+Alejandro!K$67)=0,NA(),Alejandro!K66/(Alejandro!K$65+Alejandro!K$66+Alejandro!K$67)) -> 0.39834398 | J25: =IF((Alejandro!L$65+Alejandro!L$66+Alejandro!L$67)=0,NA(),Alejandro!L66/(Alejandro!L$65+Alejandro!L$66+Alejandro!L$67)) -> 0.42224711 | K25: =IF((Alejandro!M$65+Alejandro!M$66+Alejandro!M$67)=0,NA(),Alejandro!M66/(Alejandro!M$65+Alejandro!M$66+Alejandro!M$67)) -> 0.41504498 | L25: =IF((Alejandro!N$65+Alejandro!N$66+Alejandro!N$67)=0,NA(),Alejandro!N66/(Alejandro!N$65+Alejandro!N$66+Alejandro!N$67)) -> 0.42463338 | ... V25: =IF((Alejandro!X$65+Alejandro!X$66+Alejandro!X$67)=0,NA(),Alejandro!X66/(Alejandro!X$65+Alejandro!X$66+Alejandro!X$67)) -> 0.44392265
C26: Otro | D26: =Alejandro!F70/(Alejandro!$F$68+Alejandro!$F$69+Alejandro!$F$70) -> 0.12718483 | E26: =IF((Alejandro!G$65+Alejandro!G$66+Alejandro!G$67)=0,NA(),Alejandro!G67/(Alejandro!G$65+Alejandro!G$66+Alejandro!G$67)) -> 0.18333333 | F26: =IF((Alejandro!H$65+Alejandro!H$66+Alejandro!H$67)=0,NA(),Alejandro!H67/(Alejandro!H$65+Alejandro!H$66+Alejandro!H$67)) -> 0.33333333 | G26: =IF((Alejandro!I$65+Alejandro!I$66+Alejandro!I$67)=0,NA(),Alejandro!I67/(Alejandro!I$65+Alejandro!I$66+Alejandro!I$67)) -> 0.27932106 | H26: =IF((Alejandro!J$65+Alejandro!J$66+Alejandro!J$67)=0,NA(),Alejandro!J67/(Alejandro!J$65+Alejandro!J$66+Alejandro!J$67)) -> 0.25486313 | I26: =IF((Alejandro!K$65+Alejandro!K$66+Alejandro!K$67)=0,NA(),Alejandro!K67/(Alejandro!K$65+Alejandro!K$66+Alejandro!K$67)) -> 0.18894603 | J26: =IF((Alejandro!L$65+Alejandro!L$66+Alejandro!L$67)=0,NA(),Alejandro!L67/(Alejandro!L$65+Alejandro!L$66+Alejandro!L$67)) -> 0.16879641 | K26: =IF((Alejandro!M$65+Alejandro!M$66+Alejandro!M$67)=0,NA(),Alejandro!M67/(Alejandro!M$65+Alejandro!M$66+Alejandro!M$67)) -> 0.14697127 | L26: =IF((Alejandro!N$65+Alejandro!N$66+Alejandro!N$67)=0,NA(),Alejandro!N67/(Alejandro!N$65+Alejandro!N$66+Alejandro!N$67)) -> 0.13454149 | ... V26: =IF((Alejandro!X$65+Alejandro!X$66+Alejandro!X$67)=0,NA(),Alejandro!X67/(Alejandro!X$65+Alejandro!X$66+Alejandro!X$67)) -> 0.12718483
B27: Delta Amacuro | C27: Lizzeta Hernández | D27: =Alejandro!F77/(Alejandro!$F$77+Alejandro!$F$78+Alejandro!$F$79) -> 0.78367003 | E27: =IF((Alejandro!G$74+Alejandro!G$75+Alejandro!G$76)=0,NA(),Alejandro!G74/(Alejandro!G$74+Alejandro!G$75+Alejandro!G$76)) -> 0.76923077 | F27: =IF((Alejandro!H$74+Alejandro!H$75+Alejandro!H$76)=0,NA(),Alejandro!H74/(Alejandro!H$74+Alejandro!H$75+Alejandro!H$76)) -> 0.73214286 | G27: =IF((Alejandro!I$74+Alejandro!I$75+Alejandro!I$76)=0,NA(),Alejandro!I74/(Alejandro!I$74+Alejandro!I$75+Alejandro!I$76)) -> 0.74615385 | H27: =IF((Alejandro!J$74+Alejandro!J$75+Alejandro!J$76)=0,NA(),Alejandro!J74/(Alejandro!J$74+Alejandro!J$75+Alejandro!J$76)) -> 0.7244898 | I27: =IF((Alejandro!K$74+Alejandro!K$75+Alejandro!K$76)=0,NA(),Alejandro!K74/(Alejandro!K$74+Alejandro!K$75+Alejandro!K$76)) -> 0.74698795 | J27: =IF((Alejandro!L$74+Alejandro!L$75+Alejandro!L$76)=0,NA(),Alejandro!L74/(Alejandro!L$74+Alejandro!L$75+Alejandro!L$76)) -> 0.76012461 | K27: =IF((Alejandro!M$74+Alejandro!M$75+Alejandro!M$76)=0,NA(),Alejandro!M74/(Alejandro!M$74+Alejandro!M$75+Alejandro!M$76)) -> 0.77402597 | L27: =IF((Alejandro!N$74+Alejandro!N$75+Alejandro!N$76)=0,NA(),Alejandro!N74/(Alejandro!N$74+Alejandro!N$75+Alejandro!N$76)) -> 0.7775378 | ... V27: =IF((Alejandro!X$74+Alejandro!X$75+Alejandro!X$76)=0,NA(),Alejandro!X74/(Alejandro!X$74+Alejandro!X$75+Alejandro!X$76)) -> 0.78367003
C28: Arévalo Salazar | D28: =Alejandro!F78/(Alejandro!$F$77+Alejandro!$F$78+Alejandro!$F$79) -> 0.19191919 | E28: =IF((Alejandro!G$74+Alejandro!G$75+Alejandro!G$76)=0,NA(),Alejandro!G75/(Alejandro!G$74+Alejandro!G$75+Alejandro!G$76)) -> 0.23076923 | F28: =IF((Alejandro!H$74+Alejandro!H$75+Alejandro!H$76)=0,NA(),Alejandro!H75/(Alejandro!H$74+Alejandro!H$75+Alejandro!H$76)) -> 0.26785714 | G28: =IF((Alejandro!I$74+Alejandro!I$75+Alejandro!I$76)=0,NA(),Alejandro!I75/(Alejandro!I$74+Alejandro!I$75+Alejandro!I$76)) -> 0.23076923 | H28: =IF((Alejandro!J$74+Alejandro!J$75+Alejandro!J$76)=0,NA(),Alejandro!J75/(Alejandro!J$74+Alejandro!J$75+Alejandro!J$76)) -> 0.25 | I28: =IF((Alejandro!K$74+Alejandro!K$75+Alejandro!K$76)=0,NA(),Alejandro!K75/(Alejandro!K$74+Alejandro!K$75+Alejandro!K$76)) -> 0.22891566 | J28: =IF((Alejandro!L$74+Alejandro!L$75+Alejandro!L$76)=0,NA(),Alejandro!L75/(Alejandro!L$74+Alejandro!L$75+Alejandro!L$76)) -> 0.21806854 | K28: =IF((Alejandro!M$74+Alejandro!M$75+Alejandro!M$76)=0,NA(),Alejandro!M75/(Alejandro!M$74+Alejandro!M$75+Alejandro!M$76)) -> 0.20779221 | L28: =IF((Alejandro!N$74+Alejandro!N$75+Alejandro!N$76)=0,NA(),Alejandro!N75/(Alejandro!N$74+Alejandro!N$75+Alejandro!N$76)) -> 0.20518359 | ... V28: =IF((Alejandro!X$74+Alejandro!X$75+Alejandro!X$76)=0,NA(),Alejandro!X75/(Alejandro!X$74+Alejandro!X$75+Alejandro!X$76)) -> 0.19191919
C29: Otro | D29: =Alejandro!F79/(Alejandro!$F$77+Alejandro!$F$78+Alejandro!$F$79) -> 0.024410774 | E29: =IF((Alejandro!G$74+Alejandro!G$75+Alejandro!G$76)=0,NA(),Alejandro!G76/(Alejandro!G$74+Alejandro!G$75+Alejandro!G$76)) -> 0 | F29: =IF((Alejandro!H$74+Alejandro!H$75+Alejandro!H$76)=0,NA(),Alejandro!H76/(Alejandro!H$74+Alejandro!H$75+Alejandro!H$76)) -> 0 | G29: =IF((Alejandro!I$74+Alejandro!I$75+Alejandro!I$76)=0,NA(),Alejandro!I76/(Alejandro!I$74+Alejandro!I$75+Alejandro!I$76)) -> 0.023076923 | H29: =IF((Alejandro!J$74+Alejandro!J$75+Alejandro!J$76)=0,NA(),Alejandro!J76/(Alejandro!J$74+Alejandro!J$75+Alejandro!J$76)) -> 0.025510204 | I29: =IF((Alejandro!K$74+Alejandro!K$75+Alejandro!K$76)=0,NA(),Alejandro!K76/(Alejandro!K$74+Alejandro!K$75+Alejandro!K$76)) -> 0.024096386 | J29: =IF((Alejandro!L$74+Alejandro!L$75+Alejandro!L$76)=0,NA(),Alejandro!L76/(Alejandro!L$74+Alejandro!L$75+Alejandro!L$76)) -> 0.021806854 | K29: =IF((Alejandro!M$74+Alejandro!M$75+Alejandro!M$76)=0,NA(),Alejandro!M76/(Alejandro!M$74+Alejandro!M$75+Alejandro!M$76)) -> 0.018181818 | L29: =IF((Alejandro!N$74+Alejandro!N$75+Alejandro!N$76)=0,NA(),Alejandro!N76/(Alejandro!N$74+Alejandro!N$75+Alejandro!N$76)) -> 0.017278618 | ... V29: =IF((Alejandro!X$74+Alejandro!X$75+Alejandro!X$76)=0,NA(),Alejandro!X76/(Alejandro!X$74+Alejandro!X$75+Alejandro!X$76)) -> 0.024410774
B30: Falcon | C30: Stella Lugo | D30: =Alejandro!F86/(Alejandro!$F$86+Alejandro!$F$87+Alejandro!$F$88) -> 0.52758748 | E30: =IF((Alejandro!G$83+Alejandro!G$84+Alejandro!G$85)=0,NA(),Alejandro!G83/(Alejandro!G$83+Alejandro!G$84+Alejandro!G$85)) -> 0.56460974 | F30: =IF((Alejandro!H$83+Alejandro!H$84+Alejandro!H$85)=0,NA(),Alejandro!H83/(Alejandro!H$83+Alejandro!H$84+Alejandro!H$85)) -> 0.56624596 | G30: =IF((Alejandro!I$83+Alejandro!I$84+Alejandro!I$85)=0,NA(),Alejandro!I83/(Alejandro!I$83+Alejandro!I$84+Alejandro!I$85)) -> 0.5382963 | H30: =IF((Alejandro!J$83+Alejandro!J$84+Alejandro!J$85)=0,NA(),Alejandro!J83/(Alejandro!J$83+Alejandro!J$84+Alejandro!J$85)) -> 0.54641444 | I30: =IF((Alejandro!K$83+Alejandro!K$84+Alejandro!K$85)=0,NA(),Alejandro!K83/(Alejandro!K$83+Alejandro!K$84+Alejandro!K$85)) -> 0.54565926 | J30: =IF((Alejandro!L$83+Alejandro!L$84+Alejandro!L$85)=0,NA(),Alejandro!L83/(Alejandro!L$83+Alejandro!L$84+Alejandro!L$85)) -> 0.55245217 | K30: =IF((Alejandro!M$83+Alejandro!M$84+Alejandro!M$85)=0,NA(),Alejandro!M83/(Alejandro!M$83+Alejandro!M$84+Alejandro!M$85)) -> 0.54414086 | L30: =IF((Alejandro!N$83+Alejandro!N$84+Alejandro!N$85)=0,NA(),Alejandro!N83/(Alejandro!N$83+Alejandro!N$84+Alejandro!N$85)) -> 0.54767855 | ... V30: =IF((Alejandro!X$83+Alejandro!X$84+Alejandro!X$85)=0,NA(),Alejandro!X83/(Alejandro!X$83+Alejandro!X$84+Alejandro!X$85)) -> 0.52758748
C31: Gregorio Graterol | D31: =Alejandro!F87/(Alejandro!$F$86+Alejandro!$F$87+Alejandro!$F$88) -> 0.29269941 | E31: =IF((Alejandro!G$83+Alejandro!G$84+Alejandro!G$85)=0,NA(),Alejandro!G84/(Alejandro!G$83+Alejandro!G$84+Alejandro!G$85)) -> 0.32605129 | F31: =IF((Alejandro!H$83+Alejandro!H$84+Alejandro!H$85)=0,NA(),Alejandro!H84/(Alejandro!H$83+Alejandro!H$84+Alejandro!H$85)) -> 0.33028923 | G31: =IF((Alejandro!I$83+Alejandro!I$84+Alejandro!I$85)=0,NA(),Alejandro!I84/(Alejandro!I$83+Alejandro!I$84+Alejandro!I$85)) -> 0.32924538 | H31: =IF((Alejandro!J$83+Alejandro!J$84+Alejandro!J$85)=0,NA(),Alejandro!J84/(Alejandro!J$83+Alejandro!J$84+Alejandro!J$85)) -> 0.31069576 | I31: =IF((Alejandro!K$83+Alejandro!K$84+Alejandro!K$85)=0,NA(),Alejandro!K84/(Alejandro!K$83+Alejandro!K$84+Alejandro!K$85)) -> 0.3076358 | J31: =IF((Alejandro!L$83+Alejandro!L$84+Alejandro!L$85)=0,NA(),Alejandro!L84/(Alejandro!L$83+Alejandro!L$84+Alejandro!L$85)) -> 0.29285922 | K31: =IF((Alejandro!M$83+Alejandro!M$84+Alejandro!M$85)=0,NA(),Alejandro!M84/(Alejandro!M$83+Alejandro!M$84+Alejandro!M$85)) -> 0.2927279 | L31: =IF((Alejandro!N$83+Alejandro!N$84+Alejandro!N$85)=0,NA(),Alejandro!N84/(Alejandro!N$83+Alejandro!N$84+Alejandro!N$85)) -> 0.2863691 | ... V31: =IF((Alejandro!X$83+Alejandro!X$84+Alejandro!X$85)=0,NA(),Alejandro!X84/(Alejandro!X$83+Alejandro!X$84+Alejandro!X$85)) -> 0.29269941
C32: Otro | D32: =Alejandro!F88/(Alejandro!$F$86+Alejandro!$F$87+Alejandro!$F$88) -> 0.17971311 | E32: =IF((Alejandro!G$83+Alejandro!G$84+Alejandro!G$85)=0,NA(),Alejandro!G85/(Alejandro!G$83+Alejandro!G$84+Alejandro!G$85)) -> 0.10933897 | F32: =IF((Alejandro!H$83+Alejandro!H$84+Alejandro!H$85)=0,NA(),Alejandro!H85/(Alejandro!H$83+Alejandro!H$84+Alejandro!H$85)) -> 0.1034648 | G32: =IF((Alejandro!I$83+Alejandro!I$84+Alejandro!I$85)=0,NA(),Alejandro!I85/(Alejandro!I$83+Alejandro!I$84+Alejandro!I$85)) -> 0.13245832 | H32: =IF((Alejandro!J$83+Alejandro!J$84+Alejandro!J$85)=0,NA(),Alejandro!J85/(Alejandro!J$83+Alejandro!J$84+Alejandro!J$85)) -> 0.14288981 | I32: =IF((Alejandro!K$83+Alejandro!K$84+Alejandro!K$85)=0,NA(),Alejandro!K85/(Alejandro!K$83+Alejandro!K$84+Alejandro!K$85)) -> 0.14670494 | J32: =IF((Alejandro!L$83+Alejandro!L$84+Alejandro!L$85)=0,NA(),Alejandro!L85/(Alejandro!L$83+Alejandro!L$84+Alejandro!L$85)) -> 0.15468861 | K32: =IF((Alejandro!M$83+Alejandro!M$84+Alejandro!M$85)=0,NA(),Alejandro!M85/(Alejandro!M$83+Alejandro!M$84+Alejandro!M$85)) -> 0.16313124 | L32: =IF((Alejandro!N$83+Alejandro!N$84+Alejandro!N$85)=0,NA(),Alejandro!N85/(Alejandro!N$83+Alejandro!N$84+Alejandro!N$85)) -> 0.16595235 | ... V32: =IF((Alejandro!X$83+Alejandro!X$84+Alejandro!X$85)=0,NA(),Alejandro!X85/(Alejandro!X$83+Alejandro!X$84+Alejandro!X$85)) -> 0.17971311
B33: Guarico | C33: Ramón Rodríguez Chacín | D33: =Alejandro!F95/(Alejandro!$F$95+Alejandro!$F$96+Alejandro!$F$97) -> 0.67786527 | E33: =IF((Alejandro!G$92+Alejandro!G$93+Alejandro!G$94)=0,NA(),Alejandro!G92/(Alejandro!G$92+Alejandro!G$93+Alejandro!G$94)) -> 0.86294032 | F33: =IF((Alejandro!H$92+Alejandro!H$93+Alejandro!H$94)=0,NA(),Alejandro!H92/(Alejandro!H$92+Alejandro!H$93+Alejandro!H$94)) -> 0.77036579 | G33: =IF((Alejandro!I$92+Alejandro!I$93+Alejandro!I$94)=0,NA(),Alejandro!I92/(Alejandro!I$92+Alejandro!I$93+Alejandro!I$94)) -> 0.71259159 | H33: =IF((Alejandro!J$92+Alejandro!J$93+Alejandro!J$94)=0,NA(),Alejandro!J92/(Alejandro!J$92+Alejandro!J$93+Alejandro!J$94)) -> 0.71359867 | I33: =IF((Alejandro!K$92+Alejandro!K$93+Alejandro!K$94)=0,NA(),Alejandro!K92/(Alejandro!K$92+Alejandro!K$93+Alejandro!K$94)) -> 0.7155035 | J33: =IF((Alejandro!L$92+Alejandro!L$93+Alejandro!L$94)=0,NA(),Alejandro!L92/(Alejandro!L$92+Alejandro!L$93+Alejandro!L$94)) -> 0.71998122 | K33: =IF((Alejandro!M$92+Alejandro!M$93+Alejandro!M$94)=0,NA(),Alejandro!M92/(Alejandro!M$92+Alejandro!M$93+Alejandro!M$94)) -> 0.71286651 | L33: =IF((Alejandro!N$92+Alejandro!N$93+Alejandro!N$94)=0,NA(),Alejandro!N92/(Alejandro!N$92+Alejandro!N$93+Alejandro!N$94)) -> 0.70542081 | ... V33: =IF((Alejandro!X$92+Alejandro!X$93+Alejandro!X$94)=0,NA(),Alejandro!X92/(Alejandro!X$92+Alejandro!X$93+Alejandro!X$94)) -> 0.67786527
C34: José Gonzalez | D34: =Alejandro!F96/(Alejandro!$F$95+Alejandro!$F$96+Alejandro!$F$97) -> 0.28708951 | E34: =IF((Alejandro!G$92+Alejandro!G$93+Alejandro!G$94)=0,NA(),Alejandro!G93/(Alejandro!G$92+Alejandro!G$93+Alejandro!G$94)) -> 0.11252687 | F34: =IF((Alejandro!H$92+Alejandro!H$93+Alejandro!H$94)=0,NA(),Alejandro!H93/(Alejandro!H$92+Alejandro!H$93+Alejandro!H$94)) -> 0.19719947 | G34: =IF((Alejandro!I$92+Alejandro!I$93+Alejandro!I$94)=0,NA(),Alejandro!I93/(Alejandro!I$92+Alejandro!I$93+Alejandro!I$94)) -> 0.26312495 | H34: =IF((Alejandro!J$92+Alejandro!J$93+Alejandro!J$94)=0,NA(),Alejandro!J93/(Alejandro!J$92+Alejandro!J$93+Alejandro!J$94)) -> 0.26831653 | I34: =IF((Alejandro!K$92+Alejandro!K$93+Alejandro!K$94)=0,NA(),Alejandro!K93/(Alejandro!K$92+Alejandro!K$93+Alejandro!K$94)) -> 0.26572046 | J34: =IF((Alejandro!L$92+Alejandro!L$93+Alejandro!L$94)=0,NA(),Alejandro!L93/(Alejandro!L$92+Alejandro!L$93+Alejandro!L$94)) -> 0.25882427 | K34: =IF((Alejandro!M$92+Alejandro!M$93+Alejandro!M$94)=0,NA(),Alejandro!M93/(Alejandro!M$92+Alejandro!M$93+Alejandro!M$94)) -> 0.26500703 | L34: =IF((Alejandro!N$92+Alejandro!N$93+Alejandro!N$94)=0,NA(),Alejandro!N93/(Alejandro!N$92+Alejandro!N$93+Alejandro!N$94)) -> 0.26631335 | ... V34: =IF((Alejandro!X$92+Alejandro!X$93+Alejandro!X$94)=0,NA(),Alejandro!X93/(Alejandro!X$92+Alejandro!X$93+Alejandro!X$94)) -> 0.28708951
C35: Otro | D35: =Alejandro!F97/(Alejandro!$F$95+Alejandro!$F$96+Alejandro!$F$97) -> 0.03504522 | E35: =IF((Alejandro!G$92+Alejandro!G$93+Alejandro!G$94)=0,NA(),Alejandro!G94/(Alejandro!G$92+Alejandro!G$93+Alejandro!G$94)) -> 0.024532809 | F35: =IF((Alejandro!H$92+Alejandro!H$93+Alejandro!H$94)=0,NA(),Alejandro!H94/(Alejandro!H$92+Alejandro!H$93+Alejandro!H$94)) -> 0.032434739 | G35: =IF((Alejandro!I$92+Alejandro!I$93+Alejandro!I$94)=0,NA(),Alejandro!I94/(Alejandro!I$92+Alejandro!I$93+Alejandro!I$94)) -> 0.024283453 | H35: =IF((Alejandro!J$92+Alejandro!J$93+Alejandro!J$94)=0,NA(),Alejandro!J94/(Alejandro!J$92+Alejandro!J$93+Alejandro!J$94)) -> 0.018084794 | I35: =IF((Alejandro!K$92+Alejandro!K$93+Alejandro!K$94)=0,NA(),Alejandro!K94/(Alejandro!K$92+Alejandro!K$93+Alejandro!K$94)) -> 0.018776044 | J35: =IF((Alejandro!L$92+Alejandro!L$93+Alejandro!L$94)=0,NA(),Alejandro!L94/(Alejandro!L$92+Alejandro!L$93+Alejandro!L$94)) -> 0.021194512 | K35: =IF((Alejandro!M$92+Alejandro!M$93+Alejandro!M$94)=0,NA(),Alejandro!M94/(Alejandro!M$92+Alejandro!M$93+Alejandro!M$94)) -> 0.022126453 | L35: =IF((Alejandro!N$92+Alejandro!N$93+Alejandro!N$94)=0,NA(),Alejandro!N94/(Alejandro!N$92+Alejandro!N$93+Alejandro!N$94)) -> 0.028265841 | ... V35: =IF((Alejandro!X$92+Alejandro!X$93+Alejandro!X$94)=0,NA(),Alejandro!X94/(Alejandro!X$92+Alejandro!X$93+Alejandro!X$94)) -> 0.03504522
B36: Lara | C36: Luis Reyes Reyes | D36: =Alejandro!F104/(Alejandro!$F$104+Alejandro!$F$105+Alejandro!$F$106) -> 0.35661103 | E36: =IF((Alejandro!G$101+Alejandro!G$102+Alejandro!G$103)=0,NA(),Alejandro!G101/(Alejandro!G$101+Alejandro!G$102+Alejandro!G$103)) -> 0.26032967 | F36: =IF((Alejandro!H$101+Alejandro!H$102+Alejandro!H$103)=0,NA(),Alejandro!H101/(Alejandro!H$101+Alejandro!H$102+Alejandro!H$103)) -> 0.35416175 | G36: =IF((Alejandro!I$101+Alejandro!I$102+Alejandro!I$103)=0,NA(),Alejandro!I101/(Alejandro!I$101+Alejandro!I$102+Alejandro!I$103)) -> 0.34839138 | H36: =IF((Alejandro!J$101+Alejandro!J$102+Alejandro!J$103)=0,NA(),Alejandro!J101/(Alejandro!J$101+Alejandro!J$102+Alejandro!J$103)) -> 0.35762374 | I36: =IF((Alejandro!K$101+Alejandro!K$102+Alejandro!K$103)=0,NA(),Alejandro!K101/(Alejandro!K$101+Alejandro!K$102+Alejandro!K$103)) -> 0.34884599 | J36: =IF((Alejandro!L$101+Alejandro!L$102+Alejandro!L$103)=0,NA(),Alejandro!L101/(Alejandro!L$101+Alejandro!L$102+Alejandro!L$103)) -> 0.32998218 | K36: =IF((Alejandro!M$101+Alejandro!M$102+Alejandro!M$103)=0,NA(),Alejandro!M101/(Alejandro!M$101+Alejandro!M$102+Alejandro!M$103)) -> 0.32812304 | L36: =IF((Alejandro!N$101+Alejandro!N$102+Alejandro!N$103)=0,NA(),Alejandro!N101/(Alejandro!N$101+Alejandro!N$102+Alejandro!N$103)) -> 0.35091709 | ... V36: =IF((Alejandro!X$101+Alejandro!X$102+Alejandro!X$103)=0,NA(),Alejandro!X101/(Alejandro!X$101+Alejandro!X$102+Alejandro!X$103)) -> 0.35661103
C37: Henri Falcón | D37: =Alejandro!F105/(Alejandro!$F$104+Alejandro!$F$105+Alejandro!$F$106) -> 0.55700781 | E37: =IF((Alejandro!G$101+Alejandro!G$102+Alejandro!G$103)=0,NA(),Alejandro!G102/(Alejandro!G$101+Alejandro!G$102+Alejandro!G$103)) -> 0.63424936 | F37: =IF((Alejandro!H$101+Alejandro!H$102+Alejandro!H$103)=0,NA(),Alejandro!H102/(Alejandro!H$101+Alejandro!H$102+Alejandro!H$103)) -> 0.61058896 | G37: =IF((Alejandro!I$101+Alejandro!I$102+Alejandro!I$103)=0,NA(),Alejandro!I102/(Alejandro!I$101+Alejandro!I$102+Alejandro!I$103)) -> 0.62331252 | H37: =IF((Alejandro!J$101+Alejandro!J$102+Alejandro!J$103)=0,NA(),Alejandro!J102/(Alejandro!J$101+Alejandro!J$102+Alejandro!J$103)) -> 0.61560063 | I37: =IF((Alejandro!K$101+Alejandro!K$102+Alejandro!K$103)=0,NA(),Alejandro!K102/(Alejandro!K$101+Alejandro!K$102+Alejandro!K$103)) -> 0.62109475 | J37: =IF((Alejandro!L$101+Alejandro!L$102+Alejandro!L$103)=0,NA(),Alejandro!L102/(Alejandro!L$101+Alejandro!L$102+Alejandro!L$103)) -> 0.64026598 | K37: =IF((Alejandro!M$101+Alejandro!M$102+Alejandro!M$103)=0,NA(),Alejandro!M102/(Alejandro!M$101+Alejandro!M$102+Alejandro!M$103)) -> 0.64490553 | L37: =IF((Alejandro!N$101+Alejandro!N$102+Alejandro!N$103)=0,NA(),Alejandro!N102/(Alejandro!N$101+Alejandro!N$102+Alejandro!N$103)) -> 0.62312057 | ... V37: =IF((Alejandro!X$101+Alejandro!X$102+Alejandro!X$103)=0,NA(),Alejandro!X102/(Alejandro!X$101+Alejandro!X$102+Alejandro!X$103)) -> 0.55700781
C38: Otro | D38: =Alejandro!F106/(Alejandro!$F$104+Alejandro!$F$105+Alejandro!$F$106) -> 0.086381165 | E38: =IF((Alejandro!G$101+Alejandro!G$102+Alejandro!G$103)=0,NA(),Alejandro!G103/(Alejandro!G$101+Alejandro!G$102+Alejandro!G$103)) -> 0.10542097 | F38: =IF((Alejandro!H$101+Alejandro!H$102+Alejandro!H$103)=0,NA(),Alejandro!H103/(Alejandro!H$101+Alejandro!H$102+Alejandro!H$103)) -> 0.035249288 | G38: =IF((Alejandro!I$101+Alejandro!I$102+Alejandro!I$103)=0,NA(),Alejandro!I103/(Alejandro!I$101+Alejandro!I$102+Alejandro!I$103)) -> 0.028296108 | H38: =IF((Alejandro!J$101+Alejandro!J$102+Alejandro!J$103)=0,NA(),Alejandro!J103/(Alejandro!J$101+Alejandro!J$102+Alejandro!J$103)) -> 0.026775628 | I38: =IF((Alejandro!K$101+Alejandro!K$102+Alejandro!K$103)=0,NA(),Alejandro!K103/(Alejandro!K$101+Alejandro!K$102+Alejandro!K$103)) -> 0.030059256 | J38: =IF((Alejandro!L$101+Alejandro!L$102+Alejandro!L$103)=0,NA(),Alejandro!L103/(Alejandro!L$101+Alejandro!L$102+Alejandro!L$103)) -> 0.02975184 | K38: =IF((Alejandro!M$101+Alejandro!M$102+Alejandro!M$103)=0,NA(),Alejandro!M103/(Alejandro!M$101+Alejandro!M$102+Alejandro!M$103)) -> 0.026971425 | L38: =IF((Alejandro!N$101+Alejandro!N$102+Alejandro!N$103)=0,NA(),Alejandro!N103/(Alejandro!N$101+Alejandro!N$102+Alejandro!N$103)) -> 0.025962336 | ... V38: =IF((Alejandro!X$101+Alejandro!X$102+Alejandro!X$103)=0,NA(),Alejandro!X103/(Alejandro!X$101+Alejandro!X$102+Alejandro!X$103)) -> 0.086381165
B39: Merida | C39: Alexis Ramírez | D39: =Alejandro!F113/(Alejandro!$F$113+Alejandro!$F$114+Alejandro!$F$115) -> 0.48301423 | E39: =IF((Alejandro!G$110+Alejandro!G$111+Alejandro!G$112)=0,NA(),Alejandro!G110/(Alejandro!G$110+Alejandro!G$111+Alejandro!G$112)) -> 0.25375863 | F39: =IF((Alejandro!H$110+Alejandro!H$111+Alejandro!H$112)=0,NA(),Alejandro!H110/(Alejandro!H$110+Alejandro!H$111+Alejandro!H$112)) -> 0.37762859 | G39: =IF((Alejandro!I$110+Alejandro!I$111+Alejandro!I$112)=0,NA(),Alejandro!I110/(Alejandro!I$110+Alejandro!I$111+Alejandro!I$112)) -> 0.4439804 | H39: =IF((Alejandro!J$110+Alejandro!J$111+Alejandro!J$112)=0,NA(),Alejandro!J110/(Alejandro!J$110+Alejandro!J$111+Alejandro!J$112)) -> 0.47138271 | I39: =IF((Alejandro!K$110+Alejandro!K$111+Alejandro!K$112)=0,NA(),Alejandro!K110/(Alejandro!K$110+Alejandro!K$111+Alejandro!K$112)) -> 0.50083173 | J39: =IF((Alejandro!L$110+Alejandro!L$111+Alejandro!L$112)=0,NA(),Alejandro!L110/(Alejandro!L$110+Alejandro!L$111+Alejandro!L$112)) -> 0.51058639 | K39: =IF((Alejandro!M$110+Alejandro!M$111+Alejandro!M$112)=0,NA(),Alejandro!M110/(Alejandro!M$110+Alejandro!M$111+Alejandro!M$112)) -> 0.50495367 | L39: =IF((Alejandro!N$110+Alejandro!N$111+Alejandro!N$112)=0,NA(),Alejandro!N110/(Alejandro!N$110+Alejandro!N$111+Alejandro!N$112)) -> 0.4986371 | ... V39: =IF((Alejandro!X$110+Alejandro!X$111+Alejandro!X$112)=0,NA(),Alejandro!X110/(Alejandro!X$110+Alejandro!X$111+Alejandro!X$112)) -> 0.48301423
C40: Lester Rodríguez | D40: =Alejandro!F114/(Alejandro!$F$113+Alejandro!$F$114+Alejandro!$F$115) -> 0.39379114 | E40: =IF((Alejandro!G$110+Alejandro!G$111+Alejandro!G$112)=0,NA(),Alejandro!G111/(Alejandro!G$110+Alejandro!G$111+Alejandro!G$112)) -> 0.40671983 | F40: =IF((Alejandro!H$110+Alejandro!H$111+Alejandro!H$112)=0,NA(),Alejandro!H111/(Alejandro!H$110+Alejandro!H$111+Alejandro!H$112)) -> 0.52478335 | G40: =IF((Alejandro!I$110+Alejandro!I$111+Alejandro!I$112)=0,NA(),Alejandro!I111/(Alejandro!I$110+Alejandro!I$111+Alejandro!I$112)) -> 0.47787743 | H40: =IF((Alejandro!J$110+Alejandro!J$111+Alejandro!J$112)=0,NA(),Alejandro!J111/(Alejandro!J$110+Alejandro!J$111+Alejandro!J$112)) -> 0.42202292 | I40: =IF((Alejandro!K$110+Alejandro!K$111+Alejandro!K$112)=0,NA(),Alejandro!K111/(Alejandro!K$110+Alejandro!K$111+Alejandro!K$112)) -> 0.39515365 | J40: =IF((Alejandro!L$110+Alejandro!L$111+Alejandro!L$112)=0,NA(),Alejandro!L111/(Alejandro!L$110+Alejandro!L$111+Alejandro!L$112)) -> 0.39384283 | K40: =IF((Alejandro!M$110+Alejandro!M$111+Alejandro!M$112)=0,NA(),Alejandro!M111/(Alejandro!M$110+Alejandro!M$111+Alejandro!M$112)) -> 0.39280265 | L40: =IF((Alejandro!N$110+Alejandro!N$111+Alejandro!N$112)=0,NA(),Alejandro!N111/(Alejandro!N$110+Alejandro!N$111+Alejandro!N$112)) -> 0.39222617 | ... V40: =IF((Alejandro!X$110+Alejandro!X$111+Alejandro!X$112)=0,NA(),Alejandro!X111/(Alejandro!X$110+Alejandro!X$111+Alejandro!X$112)) -> 0.39379114
...

Sheet Alejandro
C1: Votos | D1: Candidato | E1: Resultado | F1: Total | G1: 1 | H1: 2 | I1: 3 | J1: 4 | K1: 5 | L1: 6 | M1: 7 | N1: 8 | O1: 9 | P1: 10 | Q1: 11 | R1: 12 | S1: 13 | T1: 14 | U1: 15 | V1: 16 | W1: 17 | X1: 18
B2: AMAZONAS | C2: Pesados acumulados | D2: Nicia Maldonado | G2: =IF(SUM(G5:G7)=0,1,G5) -> 4 | H2: =IF(SUM(H5:H7)=0,0,G2+H5) -> 30 | I2: =IF(SUM(I5:I7)=0,0,H2+I5) -> 58 | J2: =IF(SUM(J5:J7)=0,0,I2+J5) -> 74 | K2: =IF(SUM(K5:K7)=0,0,J2+K5) -> 88 | L2: =IF(SUM(L5:L7)=0,0,K2+L5) -> 105 | M2: =IF(SUM(M5:M7)=0,0,L2+M5) -> 126 | N2: =IF(SUM(N5:N7)=0,0,M2+N5) -> 145 | O2: =IF(SUM(O5:O7)=0,0,N2+O5) -> 158 | ... X2: =IF(SUM(X5:X7)=0,0,W2+X5) -> 271
D3: Liborio Guarulla | G3: =IF(SUM(G5:G7)=0,1,G6) -> 7 | H3: =IF(SUM(H5:H7)=0,0,G3+H6) -> 37 | I3: =IF(SUM(I5:I7)=0,0,H3+I6) -> 63 | J3: =IF(SUM(J5:J7)=0,0,I3+J6) -> 87 | K3: =IF(SUM(K5:K7)=0,0,J3+K6) -> 101 | L3: =IF(SUM(L5:L7)=0,0,K3+L6) -> 108 | M3: =IF(SUM(M5:M7)=0,0,L3+M6) -> 117 | N3: =IF(SUM(N5:N7)=0,0,M3+N6) -> 140 | O3: =IF(SUM(O5:O7)=0,0,N3+O6) -> 149 | ... X3: =IF(SUM(X5:X7)=0,0,W3+X6) -> 238
D4: Otro | G4: =IF(SUM(G5:G7)=0,1,G7) -> 0 | H4: =IF(SUM(H5:H7)=0,0,G4+H7) -> 0 | I4: =IF(SUM(I5:I7)=0,0,H4+I7) -> 2 | J4: =IF(SUM(J5:J7)=0,0,I4+J7) -> 3 | K4: =IF(SUM(K5:K7)=0,0,J4+K7) -> 5 | L4: =IF(SUM(L5:L7)=0,0,K4+L7) -> 6 | M4: =IF(SUM(M5:M7)=0,0,L4+M7) -> 9 | N4: =IF(SUM(N5:N7)=0,0,M4+N7) -> 14 | O4: =IF(SUM(O5:O7)=0,0,N4+O7) -> 15 | ... X4: =IF(SUM(X5:X7)=0,0,W4+X7) -> 36
C5: Pesados | D5: Nicia Maldonado | E5: =F5/(F5+F6+F7) -> 0.49724771 | F5: =IF(SUM(G5:X5)=0,1,SUM(G5:X5)) -> 271 | G5: =AM!F3*AM!$B$5 -> 4 | H5: =AM!G3*AM!$B$5 -> 26 | I5: =AM!H3*AM!$B$5 -> 28 | J5: =AM!I3*AM!$B$5 -> 16 | K5: =AM!J3*AM!$B$5 -> 14 | L5: =AM!K3*AM!$B$5 -> 17 | M5: =AM!L3*AM!$B$5 -> 21 | N5: =AM!M3*AM!$B$5 -> 19 | ... X5: =AM!W3*AM!$B$5 -> 14
D6: Liborio Guarulla | E6: =F6/(F5+F6+F7) -> 0.43669725 | F6: =IF(SUM(G6:X6)=0,1,SUM(G6:X6)) -> 238 | G6: =AM!F4*AM!$B$5 -> 7 | H6: =AM!G4*AM!$B$5 -> 30 | I6: =AM!H4*AM!$B$5 -> 26 | J6: =AM!I4*AM!$B$5 -> 24 | K6: =AM!J4*AM!$B$5 -> 14 | L6: =AM!K4*AM!$B$5 -> 7 | M6: =AM!L4*AM!$B$5 -> 9 | N6: =AM!M4*AM!$B$5 -> 23 | ... X6: =AM!W4*AM!$B$5 -> 12
D7: Otro | E7: =F7/(F5+F6+F7) -> 0.066055046 | F7: =IF(SUM(G7:X7)=0,1,SUM(G7:X7)) -> 36 | G7: =AM!F5*AM!$B$5 -> 0 | H7: =AM!G5*AM!$B$5 -> 0 | I7: =AM!H5*AM!$B$5 -> 2 | J7: =AM!I5*AM!$B$5 -> 1 | K7: =AM!J5*AM!$B$5 -> 2 | L7: =AM!K5*AM!$B$5 -> 1 | M7: =AM!L5*AM!$B$5 -> 3 | N7: =AM!M5*AM!$B$5 -> 5 | ... X7: =AM!W5*AM!$B$5 -> 0
C8: Recibidos | D8: Nicia Maldonado | E8: =F8/(F8+F9+F10) -> 0.49724771 | F8: =IF(SUM(G8:X8)=0,1,SUM(G8:X8)) -> 271 | G8: =SUMIF(AM!$C$3:$C$5,"PSUV",AM!F$3:F$5) -> 4 | H8: =SUMIF(AM!$C$3:$C$5,"PSUV",AM!G$3:G$5) -> 26 | I8: =SUMIF(AM!$C$3:$C$5,"PSUV",AM!H$3:H$5) -> 28 | J8: =SUMIF(AM!$C$3:$C$5,"PSUV",AM!I$3:I$5) -> 16 | K8: =SUMIF(AM!$C$3:$C$5,"PSUV",AM!J$3:J$5) -> 14 | L8: =SUMIF(AM!$C$3:$C$5,"PSUV",AM!K$3:K$5) -> 17 | M8: =SUMIF(AM!$C$3:$C$5,"PSUV",AM!L$3:L$5) -> 21 | N8: =SUMIF(AM!$C$3:$C$5,"PSUV",AM!M$3:M$5) -> 19 | ... X8: =SUMIF(AM!$C$3:$C$5,"PSUV",AM!W$3:W$5) -> 14
