Workbook
Name Capriles: Tabla_Transcripcion.accdb[[#All],[capriles]]
Name Centro: Tabla_Transcripcion.accdb[[#All],[centro]]
Name Chavez: Tabla_Transcripcion.accdb[[#All],[chavez]]
Name codigo: Tabla_Transcripcion.accdb[[#All],[cod]]
Name Municipio: #REF!
Name Otro: Tabla_Transcripcion.accdb[[#All],[otro]]
Name PesosM: #REF!
Name totalv: Tabla_Transcripcion.accdb[[#All],[totalv]]
Name Turno: Tabla_Transcripcion.accdb[[#All],[turno]]

Sheet Entrada
A2: cod | B2: centro | C2: turno | D2: chavez | E2: capriles | F2: otro | G2: totalv
A3: 2111 | B3: 111 | C3: 11 | D3: 0 | E3: 1 | F3: 0 | G3: 1
A4: 3111 | B4: 111 | C4: 11 | D4: 7 | E4: 3 | F4: 0 | G4: 10
A5: 1112 | B5: 112 | C5: 11 | D5: 7 | E5: 10 | F5: 0 | G5: 17
A6: 2110 | B6: 110 | C6: 11 | D6: 7 | E6: 1 | F6: 0 | G6: 8
A7: 2112 | B7: 112 | C7: 11 | D7: 4 | E7: 3 | F7: 0 | G7: 7
A8: 1044 | B8: 44 | C8: 1 | D8: 9 | E8: 11 | F8: 0 | G8: 20
A9: 2052 | B9: 52 | C9: 1 | D9: 8 | E9: 1 | F9: 1 | G9: 10
A10: 3058 | B10: 58 | C10: 1 | D10: 18 | E10: 1 | F10: 0 | G10: 19
A11: 5048 | B11: 48 | C11: 1 | D11: 13 | E11: 3 | F11: 0 | G11: 16
A12: 1060 | B12: 60 | C12: 2 | D12: 8 | E12: 10 | F12: 0 | G12: 18
A13: 2040 | B13: 40 | C13: 1 | D13: 18 | E13: 3 | F13: 0 | G13: 21
A14: 3097 | B14: 97 | C14: 1 | D14: 8 | E14: 2 | F14: 0 | G14: 10
... A2043: 1083 | B2043: 83 | C2043: 11 | D2043: 6 | E2043: 8 | F2043: 0 | G2043: 14

Sheet CORE
B2: CM | C2: Resultado | D2: Candidato | E2: Votos | F2: 1 | G2: 2 | H2: 3 | I2: 4 | J2: 5 | K2: 6 | L2: 7 | M2: 8 | N2: 9 | O2: 10 | P2: 11 | Q2: 12 | R2: 13 | S2: 14 | T2: 15 | U2: 16 | V2: 17 | W2: 18 | X2: 19 | Y2: 20
B3: AMAZONAS | C3: =E3/SUM($E$3:$E$5) -> 0.60930561 | D3: Chavez | E3: =SUM(F3:Y3) -> 6.7023617 | F3: =F12 -> 0.38709677 | G3: =G12 -> 0.66666667 | H3: =H12 -> 0 | I3: =I12 -> 0.47058824 | J3: =J12 -> 0.51428571 | K3: =K12 -> 1 | L3: =L12 -> 0 | M3: =M12 -> 0.75 | ... Y3: =Y12 -> 0
C4: =E4/SUM($E$3:$E$5) -> 0.38534216 | D4: Capriles | E4: =SUM(F4:Y4) -> 4.2387638 | F4: =F13 -> 0.61290323 | G4: =G13 -> 0.33333333 | H4: =H13 -> 0 | I4: =I13 -> 0.52941176 | J4: =J13 -> 0.45714286 | K4: =K13 -> 0 | L4: =L13 -> 1 | M4: =M13 -> 0.25 | ... Y4: =Y13 -> 0
C5: =E5/SUM($E$3:$E$5) -> 0.0053522235 | D5: Otro | E5: =SUM(F5:Y5) -> 0.058874459 | F5: =F14 -> 0 | G5: =G14 -> 0 | H5: =H14 -> 0 | I5: =I14 -> 0 | J5: =J14 -> 0.028571429 | K5: =K14 -> 0 | L5: =L14 -> 0 | M5: =M14 -> 0 | ... Y5: =Y14 -> 0
C6: =E6/SUM($E$6:$E$8) -> 0.58762887 | D6: Chavez | E6: =E12 -> 0.58762887 | F6: =F12 -> 0.38709677 | G6: =G12 -> 0.66666667 | H6: =H12 -> 0 | I6: =I12 -> 0.47058824 | J6: =J12 -> 0.51428571 | K6: =K12 -> 1 | L6: =L12 -> 0 | ... Y6: =Y12 -> 0
C7: =E7/SUM($E$6:$E$8) -> 0.40206186 | D7: Capriles | E7: =E13 -> 0.40206186 | F7: =F13 -> 0.61290323 | G7: =G13 -> 0.33333333 | H7: =H13 -> 0 | I7: =I13 -> 0.52941176 | J7: =J13 -> 0.45714286 | K7: =K13 -> 0 | L7: =L13 -> 1 | ... Y7: =Y13 -> 0
C8: =E8/SUM($E$6:$E$8) -> 0.010309278 | D8: Otro | E8: =E14 -> 0.010309278 | F8: =F14 -> 0 | G8: =G14 -> 0 | H8: =H14 -> 0 | I8: =I14 -> 0 | J8: =J14 -> 0.028571429 | K8: =K14 -> 0 | L8: =L14 -> 0 | ... Y8: =Y14 -> 0
B9: ATURES | C9: =E9/SUM(E9:E11) -> 0.58762887 | D9: Chavez | E9: =SUM(F9:Y9) -> 114 | F9: =SUMIFS([0]!Chavez,[0]!Centro,$B11,[0]!Turno,F$2) -> 12 | G9: =SUMIFS([0]!Chavez,[0]!Centro,$B11,[0]!Turno,G$2) -> 2 | H9: =SUMIFS([0]!Chavez,[0]!Centro,$B11,[0]!Turno,H$2) -> 0 | I9: =SUMIFS([0]!Chavez,[0]!Centro,$B11,[0]!Turno,I$2) -> 8 | J9: =SUMIFS([0]!Chavez,[0]!Centro,$B11,[0]!Turno,J$2) -> 18 | K9: =SUMIFS([0]!Chavez,[0]!Centro,$B11,[0]!Turno,K$2) -> 1 | L9: =SUMIFS([0]!Chavez,[0]!Centro,$B11,[0]!Turno,L$2) -> 0 | M9: =SUMIFS([0]!Chavez,[0]!Centro,$B11,[0]!Turno,M$2) -> 3 | ... Y9: =SUMIFS([0]!Chavez,[0]!Centro,$B11,[0]!Turno,Y$2) -> 0
C10: =E10/SUM(E9:E11) -> 0.40206186 | D10: Capriles | E10: =SUM(F10:Y10) -> 78 | F10: =SUMIFS([0]!Capriles,[0]!Centro,$B11,[0]!Turno,F$2) -> 19 | G10: =SUMIFS([0]!Capriles,[0]!Centro,$B11,[0]!Turno,G$2) -> 1 | H10: =SUMIFS([0]!Capriles,[0]!Centro,$B11,[0]!Turno,H$2) -> 0 | I10: =SUMIFS([0]!Capriles,[0]!Centro,$B11,[0]!Turno,I$2) -> 9 | J10: =SUMIFS([0]!Capriles,[0]!Centro,$B11,[0]!Turno,J$2) -> 16 | K10: =SUMIFS([0]!Capriles,[0]!Centro,$B11,[0]!Turno,K$2) -> 0 | L10: =SUMIFS([0]!Capriles,[0]!Centro,$B11,[0]!Turno,L$2) -> 2 | M10: =SUMIFS([0]!Capriles,[0]!Centro,$B11,[0]!Turno,M$2) -> 1 | ... Y10: =SUMIFS([0]!Capriles,[0]!Centro,$B11,[0]!Turno,Y$2) -> 0
B11: 153 | C11: =E11/SUM(E9:E11) -> 0.010309278 | D11: Otro | E11: =SUM(F11:Y11) -> 2 | F11: =SUMIFS([0]!Otro,[0]!Centro,$B11,[0]!Turno,F$2) -> 0 | G11: =SUMIFS([0]!Otro,[0]!Centro,$B11,[0]!Turno,G$2) -> 0 | H11: =SUMIFS([0]!Otro,[0]!Centro,$B11,[0]!Turno,H$2) -> 0 | I11: =SUMIFS([0]!Otro,[0]!Centro,$B11,[0]!Turno,I$2) -> 0 | J11: =SUMIFS([0]!Otro,[0]!Centro,$B11,[0]!Turno,J$2) -> 1 | K11: =SUMIFS([0]!Otro,[0]!Centro,$B11,[0]!Turno,K$2) -> 0 | L11: =SUMIFS([0]!Otro,[0]!Centro,$B11,[0]!Turno,L$2) -> 0 | M11: =SUMIFS([0]!Otro,[0]!Centro,$B11,[0]!Turno,M$2) -> 0 | ... Y11: =SUMIFS([0]!Otro,[0]!Centro,$B11,[0]!Turno,Y$2) -> 0
C12: =E12/SUM(E12:E14) -> 0.58762887 | D12: Chavez | E12: =IF((E9+E10+E11)=0,0,(E9*$B13)/(E9+E10+E11)) -> 0.58762887 | F12: =IF((F9+F10+F11)=0,0,(F9*$B13)/(F9+F10+F11)) -> 0.38709677 | G12: =IF((G9+G10+G11)=0,0,(G9*$B13)/(G9+G10+G11)) -> 0.66666667 | H12: =IF((H9+H10+H11)=0,0,(H9*$B13)/(H9+H10+H11)) -> 0 | I12: =IF((I9+I10+I11)=0,0,(I9*$B13)/(I9+I10+I11)) -> 0.47058824 | J12: =IF((J9+J10+J11)=0,0,(J9*$B13)/(J9+J10+J11)) -> 0.51428571 | K12: =IF((K9+K10+K11)=0,0,(K9*$B13)/(K9+K10+K11)) -> 1 | L12: =IF((L9+L10+L11)=0,0,(L9*$B13)/(L9+L10+L11)) -> 0 | ... Y12: =IF((Y9+Y10+Y11)=0,0,(Y9*$B13)/(Y9+Y10+Y11)) -> 0
B13: 1 | C13: =E13/SUM(E12:E14) -> 0.40206186 | D13: Capriles | E13: =IF((E9+E10+E11)=0,0,(E10*$B13)/(E9+E10+E11)) -> 0.40206186 | F13: =IF((F9+F10+F11)=0,0,(F10*$B13)/(F9+F10+F11)) -> 0.61290323 | G13: =IF((G9+G10+G11)=0,0,(G10*$B13)/(G9+G10+G11)) -> 0.33333333 | H13: =IF((H9+H10+H11)=0,0,(H10*$B13)/(H9+H10+H11)) -> 0 | I13: =IF((I9+I10+I11)=0,0,(I10*$B13)/(I9+I10+I11)) -> 0.52941176 | J13: =IF((J9+J10+J11)=0,0,(J10*$B13)/(J9+J10+J11)) -> 0.45714286 | K13: =IF((K9+K10+K11)=0,0,(K10*$B13)/(K9+K10+K11)) -> 0 | L13: =IF((L9+L10+L11)=0,0,(L10*$B13)/(L9+L10+L11)) -> 1 | ... Y13: =IF((Y9+Y10+Y11)=0,0,(Y10*$B13)/(Y9+Y10+Y11)) -> 0
C14: =E14/SUM(E12:E14) -> 0.010309278 | D14: Otro | E14: =IF((E9+E10+E11)=0,0,(E11*$B13)/(E9+E10+E11)) -> 0.010309278 | F14: =IF((F9+F10+F11)=0,0,(F11*$B13)/(F9+F10+F11)) -> 0 | G14: =IF((G9+G10+G11)=0,0,(G11*$B13)/(G9+G10+G11)) -> 0 | H14: =IF((H9+H10+H11)=0,0,(H11*$B13)/(H9+H10+H11)) -> 0 | I14: =IF((I9+I10+I11)=0,0,(I11*$B13)/(I9+I10+I11)) -> 0 | J14: =IF((J9+J10+J11)=0,0,(J11*$B13)/(J9+J10+J11)) -> 0.028571429 | K14: =IF((K9+K10+K11)=0,0,(K11*$B13)/(K9+K10+K11)) -> 0 | L14: =IF((L9+L10+L11)=0,0,(L11*$B13)/(L9+L10+L11)) -> 0 | ... Y14: =IF((Y9+Y10+Y11)=0,0,(Y11*$B13)/(Y9+Y10+Y11)) -> 0
B15: CM | C15: Resultado | D15: Candidato | E15: Votos | F15: 1 | G15: 2 | H15: 3 | I15: 4 | J15: 5 | K15: 6 | L15: 7 | M15: 8 | N15: 9 | O15: 10 | P15: 11 | Q15: 12 | R15: 13 | S15: 14 | T15: 15 | U15: 16 | V15: 17 | W15: 18 | X15: 19 | Y15: 20
B16: ANZOATEGUI | C16: =E16/SUM($E$16:$E$18) -> 0.6369537 | D16: Chavez | E16: =SUM(F16:Y16) -> 1472 | F16: =SUM(F22,F28,F34,F40,F46,F52,F58,F64) -> 189 | G16: =SUM(G22,G28,G34,G40,G46,G52,G58,G64) -> 117 | H16: =SUM(H22,H28,H34,H40,H46,H52,H58,H64) -> 184 | I16: =SUM(I22,I28,I34,I40,I46,I52,I58,I64) -> 186 | J16: =SUM(J22,J28,J34,J40,J46,J52,J58,J64) -> 206 | K16: =SUM(K22,K28,K34,K40,K46,K52,K58,K64) -> 147 | L16: =SUM(L22,L28,L34,L40,L46,L52,L58,L64) -> 193 | M16: =SUM(M22,M28,M34,M40,M46,M52,M58,M64) -> 123 | ... Y16: =SUM(Y22,Y28,Y34,Y40,Y46,Y52,Y58,Y64) -> 0
C17: =E17/SUM($E$16:$E$18) -> 0.35352661 | D17: Capriles | E17: =SUM(F17:Y17) -> 817 | F17: =SUM(F23,F29,F35,F41,F47,F53,F59,F65) -> 115 | G17: =SUM(G23,G29,G35,G41,G47,G53,G59,G65) -> 60 | H17: =SUM(H23,H29,H35,H41,H47,H53,H59,H65) -> 86 | I17: =SUM(I23,I29,I35,I41,I47,I53,I59,I65) -> 120 | J17: =SUM(J23,J29,J35,J41,J47,J53,J59,J65) -> 125 | K17: =SUM(K23,K29,K35,K41,K47,K53,K59,K65) -> 78 | L17: =SUM(L23,L29,L35,L41,L47,L53,L59,L65) -> 99 | M17: =SUM(M23,M29,M35,M41,M47,M53,M59,M65) -> 58 | ... Y17: =SUM(Y23,Y29,Y35,Y41,Y47,Y53,Y59,Y65) -> 0
C18: =E18/SUM($E$16:$E$18) -> 0.0095196884 | D18: Otro | E18: =SUM(F18:Y18) -> 22 | F18: =SUM(F24,F30,F36,F42,F48,F54,F60,F66) -> 5 | G18: =SUM(G24,G30,G36,G42,G48,G54,G60,G66) -> 2 | H18: =SUM(H24,H30,H36,H42,H48,H54,H60,H66) -> 3 | I18: =SUM(I24,I30,I36,I42,I48,I54,I60,I66) -> 0 | J18: =SUM(J24,J30,J36,J42,J48,J54,J60,J66) -> 2 | K18: =SUM(K24,K30,K36,K42,K48,K54,K60,K66) -> 2 | L18: =SUM(L24,L30,L36,L42,L48,L54,L60,L66) -> 3 | M18: =SUM(M24,M30,M36,M42,M48,M54,M60,M66) -> 5 | ... Y18: =SUM(Y24,Y30,Y36,Y42,Y48,Y54,Y60,Y66) -> 0
C19: =E19/SUM($E$19:$E$21) -> 0.64587418 | D19: Chavez | E19: =SUM(E25,E31,E37,E43,E49,E55,E61,E67) -> 0.64587418 | F19: =SUM(F25,F31,F37,F43,F49,F55,F61,F67) -> 0.61948413 | G19: =SUM(G25,G31,G37,G43,G49,G55,G61,G67) -> 0.59614116 | H19: =SUM(H25,H31,H37,H43,H49,H55,H61,H67) -> 0.63532183 | I19: =SUM(I25,I31,I37,I43,I49,I55,I61,I67) -> 0.61104209 | J19: =SUM(J25,J31,J37,J43,J49,J55,J61,J67) -> 0.61509243 | K19: =SUM(K25,K31,K37,K43,K49,K55,K61,K67) -> 0.5946978 | L19: =SUM(L25,L31,L37,L43,L49,L55,L61,L67) -> 0.65421346 | ... Y19: =SUM(Y25,Y31,Y37,Y43,Y49,Y55,Y61,Y67) -> 0
C20: =E20/SUM($E$19:$E$21) -> 0.34507589 | D20: Capriles | E20: =SUM(E26,E32,E38,E44,E50,E56,E62,E68) -> 0.34507589 | F20: =SUM(F26,F32,F38,F44,F50,F56,F62,F68) -> 0.37110951 | G20: =SUM(G26,G32,G38,G44,G50,G56,G62,G68) -> 0.22858934 | H20: =SUM(H26,H32,H38,H44,H50,H56,H62,H68) -> 0.28609911 | I20: =SUM(I26,I32,I38,I44,I50,I56,I62,I68) -> 0.38895791 | J20: =SUM(J26,J32,J38,J44,J50,J56,J62,J68) -> 0.378488 | K20: =SUM(K26,K32,K38,K44,K50,K56,K62,K68) -> 0.33712301 | L20: =SUM(L26,L32,L38,L44,L50,L56,L62,L68) -> 0.29648758 | ... Y20: =SUM(Y26,Y32,Y38,Y44,Y50,Y56,Y62,Y68) -> 0
C21: =E21/SUM($E$19:$E$21) -> 0.0090499281 | D21: Otro | E21: =SUM(E27,E33,E39,E45,E51,E57,E63,E69) -> 0.0090499281 | F21: =SUM(F27,F33,F39,F45,F51,F57,F63,F69) -> 0.009406357 | G21: =SUM(G27,G33,G39,G45,G51,G57,G63,G69) -> 0.0033745258 | H21: =SUM(H27,H33,H39,H45,H51,H57,H63,H69) -> 0.014383375 | I21: =SUM(I27,I33,I39,I45,I51,I57,I63,I69) -> 0 | J21: =SUM(J27,J33,J39,J45,J51,J57,J63,J69) -> 0.006419569 | K21: =SUM(K27,K33,K39,K45,K51,K57,K63,K69) -> 0.003983502 | L21: =SUM(L27,L33,L39,L45,L51,L57,L63,L69) -> 0.0094639382 | ... Y21: =SUM(Y27,Y33,Y39,Y45,Y51,Y57,Y63,Y69) -> 0
B22: ANACO | C22: =E22/SUM(E22:E24) -> 0.67886179 | D22: Chavez | E22: =SUM(F22:Y22) -> 167 | F22: =SUMIFS([0]!Chavez,[0]!Centro,$B24,[0]!Turno,F$15) -> 6 | G22: =SUMIFS([0]!Chavez,[0]!Centro,$B24,[0]!Turno,G$15) -> 0 | H22: =SUMIFS([0]!Chavez,[0]!Centro,$B24,[0]!Turno,H$15) -> 37 | I22: =SUMIFS([0]!Chavez,[0]!Centro,$B24,[0]!Turno,I$15) -> 34 | J22: =SUMIFS([0]!Chavez,[0]!Centro,$B24,[0]!Turno,J$15) -> 30 | K22: =SUMIFS([0]!Chavez,[0]!Centro,$B24,[0]!Turno,K$15) -> 10 | L22: =SUMIFS([0]!Chavez,[0]!Centro,$B24,[0]!Turno,L$15) -> 29 | M22: =SUMIFS([0]!Chavez,[0]!Centro,$B24,[0]!Turno,M$15) -> 9 | ... Y22: =SUMIFS([0]!Chavez,[0]!Centro,$B24,[0]!Turno,Y$15) -> 0
C23: =E23/SUM(E22:E24) -> 0.32113821 | D23: Capriles | E23: =SUM(F23:Y23) -> 79 | F23: =SUMIFS([0]!Capriles,[0]!Centro,$B24,[0]!Turno,F$15) -> 5 | G23: =SUMIFS([0]!Capriles,[0]!Centro,$B24,[0]!Turno,G$15) -> 0 | H23: =SUMIFS([0]!Capriles,[0]!Centro,$B24,[0]!Turno,H$15) -> 14 | I23: =SUMIFS([0]!Capriles,[0]!Centro,$B24,[0]!Turno,I$15) -> 8 | J23: =SUMIFS([0]!Capriles,[0]!Centro,$B24,[0]!Turno,J$15) -> 22 | K23: =SUMIFS([0]!Capriles,[0]!Centro,$B24,[0]!Turno,K$15) -> 10 | L23: =SUMIFS([0]!Capriles,[0]!Centro,$B24,[0]!Turno,L$15) -> 9 | M23: =SUMIFS([0]!Capriles,[0]!Centro,$B24,[0]!Turno,M$15) -> 3 | ... Y23: =SUMIFS([0]!Capriles,[0]!Centro,$B24,[0]!Turno,Y$15) -> 0
B24: 20 | C24: =E24/SUM(E22:E24) -> 0 | D24: Otro | E24: =SUM(F24:Y24) -> 0 | F24: =SUMIFS([0]!Otro,[0]!Centro,$B24,[0]!Turno,F$15) -> 0 | G24: =SUMIFS([0]!Otro,[0]!Centro,$B24,[0]!Turno,G$15) -> 0 | H24: =SUMIFS([0]!Otro,[0]!Centro,$B24,[0]!Turno,H$15) -> 0 | I24: =SUMIFS([0]!Otro,[0]!Centro,$B24,[0]!Turno,I$15) -> 0 | J24: =SUMIFS([0]!Otro,[0]!Centro,$B24,[0]!Turno,J$15) -> 0 | K24: =SUMIFS([0]!Otro,[0]!Centro,$B24,[0]!Turno,K$15) -> 0 | L24: =SUMIFS([0]!Otro,[0]!Centro,$B24,[0]!Turno,L$15) -> 0 | M24: =SUMIFS([0]!Otro,[0]!Centro,$B24,[0]!Turno,M$15) -> 0 | ... Y24: =SUMIFS([0]!Otro,[0]!Centro,$B24,[0]!Turno,Y$15) -> 0
C25: =E25/SUM(E25:E27) -> 0.67886179 | D25: Chavez | E25: =IF((E22+E23+E24)=0,0,(E22*$B26)/(E22+E23+E24)) -> 0.073112928 | F25: =IF((F22+F23+F24)=0,0,(F22*$B26)/(F22+F23+F24)) -> 0.058745064 | G25: =IF((G22+G23+G24)=0,0,(G22*$B26)/(G22+G23+G24)) -> 0 | H25: =IF((H22+H23+H24)=0,0,(H22*$B26)/(H22+H23+H24)) -> 0.078134775 | I25: =IF((I22+I23+I24)=0,0,(I22*$B26)/(I22+I23+I24)) -> 0.087185135 | J25: =IF((J22+J23+J24)=0,0,(J22*$B26)/(J22+J23+J24)) -> 0.062134202 | K25: =IF((K22+K23+K24)=0,0,(K22*$B26)/(K22+K23+K24)) -> 0.053849642 | L25: =IF((L22+L23+L24)=0,0,(L22*$B26)/(L22+L23+L24)) -> 0.082191559 | ... Y25: =IF((Y22+Y23+Y24)=0,0,(Y22*$B26)/(Y22+Y23+Y24)) -> 0
B26: 0.10769928 | C26: =E26/SUM(E25:E27) -> 0.32113821 | D26: Capriles | E26: =IF((E22+E23+E24)=0,0,(E23*$B26)/(E22+E23+E24)) -> 0.034586355 | F26: =IF((F22+F23+F24)=0,0,(F23*$B26)/(F22+F23+F24)) -> 0.04895422 | G26: =IF((G22+G23+G24)=0,0,(G23*$B26)/(G22+G23+G24)) -> 0 | H26: =IF((H22+H23+H24)=0,0,(H23*$B26)/(H22+H23+H24)) -> 0.029564509 | I26: =IF((I22+I23+I24)=0,0,(I23*$B26)/(I22+I23+I24)) -> 0.020514149 | J26: =IF((J22+J23+J24)=0,0,(J23*$B26)/(J22+J23+J24)) -> 0.045565082 | K26: =IF((K22+K23+K24)=0,0,(K23*$B26)/(K22+K23+K24)) -> 0.053849642 | L26: =IF((L22+L23+L24)=0,0,(L23*$B26)/(L22+L23+L24)) -> 0.025507725 | ... Y26: =IF((Y22+Y23+Y24)=0,0,(Y23*$B26)/(Y22+Y23+Y24)) -> 0
C27: =E27/SUM(E25:E27) -> 0 | D27: Otro | E27: =IF((E22+E23+E24)=0,0,(E24*$B26)/(E22+E23+E24)) -> 0 | F27: =IF((F22+F23+F24)=0,0,(F24*$B26)/(F22+F23+F24)) -> 0 | G27: =IF((G22+G23+G24)=0,0,(G24*$B26)/(G22+G23+G24)) -> 0 | H27: =IF((H22+H23+H24)=0,0,(H24*$B26)/(H22+H23+H24)) -> 0 | I27: =IF((I22+I23+I24)=0,0,(I24*$B26)/(I22+I23+I24)) -> 0 | J27: =IF((J22+J23+J24)=0,0,(J24*$B26)/(J22+J23+J24)) -> 0 | K27: =IF((K22+K23+K24)=0,0,(K24*$B26)/(K22+K23+K24)) -> 0 | L27: =IF((L22+L23+L24)=0,0,(L24*$B26)/(L22+L23+L24)) -> 0 | ... Y27: =IF((Y22+Y23+Y24)=0,0,(Y24*$B26)/(Y22+Y23+Y24)) -> 0
B28: BOLIVAR | C28: =E28/SUM(E28:E30) -> 0.58371041 | D28: Chavez | E28: =SUM(F28:Y28) -> 258 | F28: =SUMIFS([0]!Chavez,[0]!Centro,$B30,[0]!Turno,F$15) -> 51 | G28: =SUMIFS([0]!Chavez,[0]!Centro,$B30,[0]!Turno,G$15) -> 13 | H28: =SUMIFS([0]!Chavez,[0]!Centro,$B30,[0]!Turno,H$15) -> 35 | I28: =SUMIFS([0]!Chavez,[0]!Centro,$B30,[0]!Turno,I$15) -> 37 | J28: =SUMIFS([0]!Chavez,[0]!Centro,$B30,[0]!Turno,J$15) -> 31 | K28: =SUMIFS([0]!Chavez,[0]!Centro,$B30,[0]!Turno,K$15) -> 27 | L28: =SUMIFS([0]!Chavez,[0]!Centro,$B30,[0]!Turno,L$15) -> 41 | M28: =SUMIFS([0]!Chavez,[0]!Centro,$B30,[0]!Turno,M$15) -> 23 | ... Y28: =SUMIFS([0]!Chavez,[0]!Centro,$B30,[0]!Turno,Y$15) -> 0
C29: =E29/SUM(E28:E30) -> 0.40497738 | D29: Capriles | E29: =SUM(F29:Y29) -> 179 | F29: =SUMIFS([0]!Capriles,[0]!Centro,$B30,[0]!Turno,F$15) -> 41 | G29: =SUMIFS([0]!Capriles,[0]!Centro,$B30,[0]!Turno,G$15) -> 7 | H29: =SUMIFS([0]!Capriles,[0]!Centro,$B30,[0]!Turno,H$15) -> 31 | I29: =SUMIFS([0]!Capriles,[0]!Centro,$B30,[0]!Turno,I$15) -> 24 | J29: =SUMIFS([0]!Capriles,[0]!Centro,$B30,[0]!Turno,J$15) -> 24 | K29: =SUMIFS([0]!Capriles,[0]!Centro,$B30,[0]!Turno,K$15) -> 26 | L29: =SUMIFS([0]!Capriles,[0]!Centro,$B30,[0]!Turno,L$15) -> 16 | M29: =SUMIFS([0]!Capriles,[0]!Centro,$B30,[0]!Turno,M$15) -> 10 | ... Y29: =SUMIFS([0]!Capriles,[0]!Centro,$B30,[0]!Turno,Y$15) -> 0
B30: 21 | C30: =E30/SUM(E28:E30) -> 0.011312217 | D30: Otro | E30: =SUM(F30:Y30) -> 5 | F30: =SUMIFS([0]!Otro,[0]!Centro,$B30,[0]!Turno,F$15) -> 1 | G30: =SUMIFS([0]!Otro,[0]!Centro,$B30,[0]!Turno,G$15) -> 0 | H30: =SUMIFS([0]!Otro,[0]!Centro,$B30,[0]!Turno,H$15) -> 3 | I30: =SUMIFS([0]!Otro,[0]!Centro,$B30,[0]!Turno,I$15) -> 0 | J30: =SUMIFS([0]!Otro,[0]!Centro,$B30,[0]!Turno,J$15) -> 0 | K30: =SUMIFS([0]!Otro,[0]!Centro,$B30,[0]!Turno,K$15) -> 0 | L30: =SUMIFS([0]!Otro,[0]!Centro,$B30,[0]!Turno,L$15) -> 1 | M30: =SUMIFS([0]!Otro,[0]!Centro,$B30,[0]!Turno,M$15) -> 0 | ... Y30: =SUMIFS([0]!Otro,[0]!Centro,$B30,[0]!Turno,Y$15) -> 0
C31: =E31/SUM(E31:E33) -> 0.58371041 | D31: Chavez | E31: =IF((E28+E29+E30)=0,0,(E28*$B32)/(E28+E29+E30)) -> 0.1931017 | F31: =IF((F28+F29+F30)=0,0,(F28*$B32)/(F28+F29+F30)) -> 0.18141612 | G31: =IF((G28+G29+G30)=0,0,(G28*$B32)/(G28+G29+G30)) -> 0.21503146 | H31: =IF((H28+H29+H30)=0,0,(H28*$B32)/(H28+H29+H30)) -> 0.16780605 | I31: =IF((I28+I29+I30)=0,0,(I28*$B32)/(I28+I29+I30)) -> 0.20065988 | J31: =IF((J28+J29+J30)=0,0,(J28*$B32)/(J28+J29+J30)) -> 0.18646085 | K31: =IF((K28+K29+K30)=0,0,(K28*$B32)/(K28+K29+K30)) -> 0.16852974 | L31: =IF((L28+L29+L30)=0,0,(L28*$B32)/(L28+L29+L30)) -> 0.23385384 | ... Y31: =IF((Y28+Y29+Y30)=0,0,(Y28*$B32)/(Y28+Y29+Y30)) -> 0
B32: 0.33081763 | C32: =E32/SUM(E31:E33) -> 0.40497738 | D32: Capriles | E32: =IF((E28+E29+E30)=0,0,(E29*$B32)/(E28+E29+E30)) -> 0.13397366 | F32: =IF((F28+F29+F30)=0,0,(F29*$B32)/(F28+F29+F30)) -> 0.14584433 | G32: =IF((G28+G29+G30)=0,0,(G29*$B32)/(G28+G29+G30)) -> 0.11578617 | H32: =IF((H28+H29+H30)=0,0,(H29*$B32)/(H28+H29+H30)) -> 0.14862821 | I32: =IF((I28+I29+I30)=0,0,(I29*$B32)/(I28+I29+I30)) -> 0.13015776 | J32: =IF((J28+J29+J30)=0,0,(J29*$B32)/(J28+J29+J30)) -> 0.14435679 | K32: =IF((K28+K29+K30)=0,0,(K29*$B32)/(K28+K29+K30)) -> 0.1622879 | L32: =IF((L28+L29+L30)=0,0,(L29*$B32)/(L28+L29+L30)) -> 0.091260037 | ... Y32: =IF((Y28+Y29+Y30)=0,0,(Y29*$B32)/(Y28+Y29+Y30)) -> 0
C33: =E33/SUM(E31:E33) -> 0.011312217 | D33: Otro | E33: =IF((E28+E29+E30)=0,0,(E30*$B32)/(E28+E29+E30)) -> 0.0037422809 | F33: =IF((F28+F29+F30)=0,0,(F30*$B32)/(F28+F29+F30)) -> 0.0035571789 | G33: =IF((G28+G29+G30)=0,0,(G30*$B32)/(G28+G29+G30)) -> 0 | H33: =IF((H28+H29+H30)=0,0,(H30*$B32)/(H28+H29+H30)) -> 0.014383375 | I33: =IF((I28+I29+I30)=0,0,(I30*$B32)/(I28+I29+I30)) -> 0 | J33: =IF((J28+J29+J30)=0,0,(J30*$B32)/(J28+J29+J30)) -> 0 | K33: =IF((K28+K29+K30)=0,0,(K30*$B32)/(K28+K29+K30)) -> 0 | L33: =IF((L28+L29+L30)=0,0,(L30*$B32)/(L28+L29+L30)) -> 0.0057037523 | ... Y33: =IF((Y28+Y29+Y30)=0,0,(Y30*$B32)/(Y28+Y29+Y30)) -> 0
B34: DIEGO BAUTISTA URBANEJA | C34: =E34/SUM(E34:E36) -> 0.05 | D34: Chavez | E34: =SUM(F34:Y34) -> 9 | F34: =SUMIFS([0]!Chavez,[0]!Centro,$B36,[0]!Turno,F$15) -> 2 | G34: =SUMIFS([0]!Chavez,[0]!Centro,$B36,[0]!Turno,G$15) -> 2 | H34: =SUMIFS([0]!Chavez,[0]!Centro,$B36,[0]!Turno,H$15) -> 2 | I34: =SUMIFS([0]!Chavez,[0]!Centro,$B36,[0]!Turno,I$15) -> 0 | J34: =SUMIFS([0]!Chavez,[0]!Centro,$B36,[0]!Turno,J$15) -> 1 | K34: =SUMIFS([0]!Chavez,[0]!Centro,$B36,[0]!Turno,K$15) -> 1 | L34: =SUMIFS([0]!Chavez,[0]!Centro,$B36,[0]!Turno,L$15) -> 1 | M34: =SUMIFS([0]!Chavez,[0]!Centro,$B36,[0]!Turno,M$15) -> 0 | ... Y34: =SUMIFS([0]!Chavez,[0]!Centro,$B36,[0]!Turno,Y$15) -> 0
C35: =E35/SUM(E34:E36) -> 0.95 | D35: Capriles | E35: =SUM(F35:Y35) -> 171 | F35: =SUMIFS([0]!Capriles,[0]!Centro,$B36,[0]!Turno,F$15) -> 16 | G35: =SUMIFS([0]!Capriles,[0]!Centro,$B36,[0]!Turno,G$15) -> 16 | H35: =SUMIFS([0]!Capriles,[0]!Centro,$B36,[0]!Turno,H$15) -> 21 | I35: =SUMIFS([0]!Capriles,[0]!Centro,$B36,[0]!Turno,I$15) -> 20 | J35: =SUMIFS([0]!Capriles,[0]!Centro,$B36,[0]!Turno,J$15) -> 19 | K35: =SUMIFS([0]!Capriles,[0]!Centro,$B36,[0]!Turno,K$15) -> 19 | L35: =SUMIFS([0]!Capriles,[0]!Centro,$B36,[0]!Turno,L$15) -> 20 | M35: =SUMIFS([0]!Capriles,[0]!Centro,$B36,[0]!Turno,M$15) -> 20 | ... Y35: =SUMIFS([0]!Capriles,[0]!Centro,$B36,[0]!Turno,Y$15) -> 0
B36: 22 | C36: =E36/SUM(E34:E36) -> 0 | D36: Otro | E36: =SUM(F36:Y36) -> 0 | F36: =SUMIFS([0]!Otro,[0]!Centro,$B36,[0]!Turno,F$15) -> 0 | G36: =SUMIFS([0]!Otro,[0]!Centro,$B36,[0]!Turno,G$15) -> 0 | H36: =SUMIFS([0]!Otro,[0]!Centro,$B36,[0]!Turno,H$15) -> 0 | I36: =SUMIFS([0]!Otro,[0]!Centro,$B36,[0]!Turno,I$15) -> 0 | J36: =SUMIFS([0]!Otro,[0]!Centro,$B36,[0]!Turno,J$15) -> 0 | K36: =SUMIFS([0]!Otro,[0]!Centro,$B36,[0]!Turno,K$15) -> 0 | L36: =SUMIFS([0]!Otro,[0]!Centro,$B36,[0]!Turno,L$15) -> 0 | M36: =SUMIFS([0]!Otro,[0]!Centro,$B36,[0]!Turno,M$15) -> 0 | ... Y36: =SUMIFS([0]!Otro,[0]!Centro,$B36,[0]!Turno,Y$15) -> 0
C37: =E37/SUM(E37:E39) -> 0.05 | D37: Chavez | E37: =IF((E34+E35+E36)=0,0,(E34*$B38)/(E34+E35+E36)) -> 0.0019956643 | F37: =IF((F34+F35+F36)=0,0,(F34*$B38)/(F34+F35+F36)) -> 0.0044348096 | G37: =IF((G34+G35+G36)=0,0,(G34*$B38)/(G34+G35+G36)) -> 0.0044348096 | H37: =IF((H34+H35+H36)=0,0,(H34*$B38)/(H34+H35+H36)) -> 0.0034707205 | I37: =IF((I34+I35+I36)=0,0,(I34*$B38)/(I34+I35+I36)) -> 0 | J37: =IF((J34+J35+J36)=0,0,(J34*$B38)/(J34+J35+J36)) -> 0.0019956643 | K37: =IF((K34+K35+K36)=0,0,(K34*$B38)/(K34+K35+K36)) -> 0.0019956643 | L37: =IF((L34+L35+L36)=0,0,(L34*$B38)/(L34+L35+L36)) -> 0.0019006327 | ... Y37: =IF((Y34+Y35+Y36)=0,0,(Y34*$B38)/(Y34+Y35+Y36)) -> 0
B38: 0.039913286 | C38: =E38/SUM(E37:E39) -> 0.95 | D38: Capriles | E38: =IF((E34+E35+E36)=0,0,(E35*$B38)/(E34+E35+E36)) -> 0.037917622 | F38: =IF((F34+F35+F36)=0,0,(F35*$B38)/(F34+F35+F36)) -> 0.035478476 | G38: =IF((G34+G35+G36)=0,0,(G35*$B38)/(G34+G35+G36)) -> 0.035478476 | H38: =IF((H34+H35+H36)=0,0,(H35*$B38)/(H34+H35+H36)) -> 0.036442565 | I38: =IF((I34+I35+I36)=0,0,(I35*$B38)/(I34+I35+I36)) -> 0.039913286 | J38: =IF((J34+J35+J36)=0,0,(J35*$B38)/(J34+J35+J36)) -> 0.037917622 | K38: =IF((K34+K35+K36)=0,0,(K35*$B38)/(K34+K35+K36)) -> 0.037917622 | L38: =IF((L34+L35+L36)=0,0,(L35*$B38)/(L34+L35+L36)) -> 0.038012653 | ... Y38: =IF((Y34+Y35+Y36)=0,0,(Y35*$B38)/(Y34+Y35+Y36)) -> 0
C39: =E39/SUM(E37:E39) -> 0 | D39: Otro | E39: =IF((E34+E35+E36)=0,0,(E36*$B38)/(E34+E35+E36)) -> 0 | F39: =IF((F34+F35+F36)=0,0,(F36*$B38)/(F34+F35+F36)) -> 0 | G39: =IF((G34+G35+G36)=0,0,(G36*$B38)/(G34+G35+G36)) -> 0 | H39: =IF((H34+H35+H36)=0,0,(H36*$B38)/(H34+H35+H36)) -> 0 | I39: =IF((I34+I35+I36)=0,0,(I36*$B38)/(I34+I35+I36)) -> 0 | J39: =IF((J34+J35+J36)=0,0,(J36*$B38)/(J34+J35+J36)) -> 0 | K39: =IF((K34+K35+K36)=0,0,(K36*$B38)/(K34+K35+K36)) -> 0 | L39: =IF((L34+L35+L36)=0,0,(L36*$B38)/(L34+L35+L36)) -> 0 | ... Y39: =IF((Y34+Y35+Y36)=0,0,(Y36*$B38)/(Y34+Y35+Y36)) -> 0
B40: FREITES | C40: =E40/SUM(E40:E42) -> 0.68731563 | D40: Chavez | E40: =SUM(F40:Y40) -> 233 | F40: =SUMIFS([0]!Chavez,[0]!Centro,$B42,[0]!Turno,F$15) -> 26 | G40: =SUMIFS([0]!Chavez,[0]!Centro,$B42,[0]!Turno,G$15) -> 28 | H40: =SUMIFS([0]!Chavez,[0]!Centro,$B42,[0]!Turno,H$15) -> 26 | I40: =SUMIFS([0]!Chavez,[0]!Centro,$B42,[0]!Turno,I$15) -> 15 | J40: =SUMIFS([0]!Chavez,[0]!Centro,$B42,[0]!Turno,J$15) -> 39 | K40: =SUMIFS([0]!Chavez,[0]!Centro,$B42,[0]!Turno,K$15) -> 16 | L40: =SUMIFS([0]!Chavez,[0]!Centro,$B42,[0]!Turno,L$15) -> 25 | M40: =SUMIFS([0]!Chavez,[0]!Centro,$B42,[0]!Turno,M$15) -> 9 | ... Y40: =SUMIFS([0]!Chavez,[0]!Centro,$B42,[0]!Turno,Y$15) -> 0
C41: =E41/SUM(E40:E42) -> 0.28318584 | D41: Capriles | E41: =SUM(F41:Y41) -> 96 | F41: =SUMIFS([0]!Capriles,[0]!Centro,$B42,[0]!Turno,F$15) -> 15 | G41: =SUMIFS([0]!Capriles,[0]!Centro,$B42,[0]!Turno,G$15) -> 9 | H41: =SUMIFS([0]!Capriles,[0]!Centro,$B42,[0]!Turno,H$15) -> 3 | I41: =SUMIFS([0]!Capriles,[0]!Centro,$B42,[0]!Turno,I$15) -> 5 | J41: =SUMIFS([0]!Capriles,[0]!Centro,$B42,[0]!Turno,J$15) -> 16 | K41: =SUMIFS([0]!Capriles,[0]!Centro,$B42,[0]!Turno,K$15) -> 4 | L41: =SUMIFS([0]!Capriles,[0]!Centro,$B42,[0]!Turno,L$15) -> 8 | M41: =SUMIFS([0]!Capriles,[0]!Centro,$B42,[0]!Turno,M$15) -> 5 | ... Y41: =SUMIFS([0]!Capriles,[0]!Centro,$B42,[0]!Turno,Y$15) -> 0
...

Sheet VZA
E1: Total | F1: 1 | G1: 2 | H1: 3 | I1: 4 | J1: 5 | K1: 6 | L1: 7 | M1: 8 | N1: 9 | O1: 10 | P1: 11 | Q1: 12 | R1: 13 | S1: 14 | T1: 15 | U1: 16 | V1: 17 | W1: 18 | X1: 19 | Y1: 20 | AU1: Total | AV1: 1 | AW1: 2 | AX1: 3 | AY1: 4 | AZ1: 5 | BA1: 6 | BB1: 7 | BC1: 8 | BD1: 9 | BE1: 10 | BF1: 11 | BG1: 12 | BH1: 13 | BI1: 14 | BJ1: 15 | BK1: 16 | BL1: 17 | BM1: 18 | BN1: 19 | BO1: 20 | BS1: VENEZUELA | CD1: AMAZONAS | CO1: ANZOATEGUI | CZ1: APURE | DK1: ARAGUA | DV1: BARINAS | EG1: BOLIVAR | ER1: CARABOBO | FC1: COJEDES | FN1: DELTA AMACURO | FY1: DISTRITO CAPITAL | GJ1: FALCON | GU1: GUARICO | HF1: LARA | HQ1: MERIDA | IB1: MIRANDA | IM1: MONAGAS | IX1: NUEVA ESPARTA | JI1: PORTUGUESA | JT1: SUCRE | KE1: TACHIRA | KP1: TRUJILLO | LA1: VARGAS | LL1: YARACUY | LW1: ZULIA
B2: =E2/SUM($E$2:$E$4) -> 0.54043196 | C2: Chavez | D2: VENEZUELA | E2: =SUM(F2:Y2) -> 102.21475 | F2: =SUM(F5,F8,F11,F14,F17,F20,F23,F26,F29,F32,F35,F38,F41,F44,F47,F50,F53,F56,F59,F62,F65,F68,F71,F74) -> 10.229621 | G2: =SUM(G5,G8,G11,G14,G17,G20,G23,G26,G29,G32,G35,G38,G41,G44,G47,G50,G53,G56,G59,G62,G65,G68,G71,G74) -> 11.129465 | H2: =SUM(H5,H8,H11,H14,H17,H20,H23,H26,H29,H32,H35,H38,H41,H44,H47,H50,H53,H56,H59,H62,H65,H68,H71,H74) -> 11.209488 | I2: =SUM(I5,I8,I11,I14,I17,I20,I23,I26,I29,I32,I35,I38,I41,I44,I47,I50,I53,I56,I59,I62,I65,I68,I71,I74) -> 10.356013 | J2: =SUM(J5,J8,J11,J14,J17,J20,J23,J26,J29,J32,J35,J38,J41,J44,J47,J50,J53,J56,J59,J62,J65,J68,J71,J74) -> 11.278757 | K2: =SUM(K5,K8,K11,K14,K17,K20,K23,K26,K29,K32,K35,K38,K41,K44,K47,K50,K53,K56,K59,K62,K65,K68,K71,K74) -> 11.06056 | L2: =SUM(L5,L8,L11,L14,L17,L20,L23,L26,L29,L32,L35,L38,L41,L44,L47,L50,L53,L56,L59,L62,L65,L68,L71,L74) -> 9.9384661 | M2: =SUM(M5,M8,M11,M14,M17,M20,M23,M26,M29,M32,M35,M38,M41,M44,M47,M50,M53,M56,M59,M62,M65,M68,M71,M74) -> 10.676346 | ... Y2: =SUM(Y5,Y8,Y11,Y14,Y17,Y20,Y23,Y26,Y29,Y32,Y35,Y38,Y41,Y44,Y47,Y50,Y53,Y56,Y59,Y62,Y65,Y68,Y71,Y74) -> 0 | AR2: =AU2/SUM($AU2:$AU4) -> 0.50937308 | AS2: Chavez | AU2: =SUM(AU5,AU8,AU11,AU14,AU17,AU20,AU23,AU26,AU29,AU32,AU35,AU38,AU41,AU44,AU47,AU50,AU53,AU56,AU59,AU62,AU65,AU68,AU71,AU74) -> 50.937308 | AV2: =SUM(AV5,AV8,AV11,AV14,AV17,AV20,AV23,AV26,AV29,AV32,AV35,AV38,AV41,AV44,AV47,AV50,AV53,AV56,AV59,AV62,AV65,AV68,AV71,AV74) -> 51.877275 | AW2: =SUM(AW5,AW8,AW11,AW14,AW17,AW20,AW23,AW26,AW29,AW32,AW35,AW38,AW41,AW44,AW47,AW50,AW53,AW56,AW59,AW62,AW65,AW68,AW71,AW74) -> 54.878429 | AX2: =SUM(AX5,AX8,AX11,AX14,AX17,AX20,AX23,AX26,AX29,AX32,AX35,AX38,AX41,AX44,AX47,AX50,AX53,AX56,AX59,AX62,AX65,AX68,AX71,AX74) -> 52.683802 | AY2: =SUM(AY5,AY8,AY11,AY14,AY17,AY20,AY23,AY26,AY29,AY32,AY35,AY38,AY41,AY44,AY47,AY50,AY53,AY56,AY59,AY62,AY65,AY68,AY71,AY74) -> 46.810238 | AZ2: =SUM(AZ5,AZ8,AZ11,AZ14,AZ17,AZ20,AZ23,AZ26,AZ29,AZ32,AZ35,AZ38,AZ41,AZ44,AZ47,AZ50,AZ53,AZ56,AZ59,AZ62,AZ65,AZ68,AZ71,AZ74) -> 51.277845 | BA2: =SUM(BA5,BA8,BA11,BA14,BA17,BA20,BA23,BA26,BA29,BA32,BA35,BA38,BA41,BA44,BA47,BA50,BA53,BA56,BA59,BA62,BA65,BA68,BA71,BA74) -> 48.511776 | BB2: =SUM(BB5,BB8,BB11,BB14,BB17,BB20,BB23,BB26,BB29,BB32,BB35,BB38,BB41,BB44,BB47,BB50,BB53,BB56,BB59,BB62,BB65,BB68,BB71,BB74) -> 48.83089 | ... BO2: =SUM(BO5,BO8,BO11,BO14,BO17,BO20,BO23,BO26,BO29,BO32,BO35,BO38,BO41,BO44,BO47,BO50,BO53,BO56,BO59,BO62,BO65,BO68,BO71,BO74) -> 0 | BS2: Hugo Chávez | BV2: Henrique Capriles | BY2: Otros Candidatos | CD2: Hugo Chávez | CG2: Henrique Capriles | CJ2: Otros Candidatos | CO2: Hugo Chávez | CR2: Henrique Capriles | CU2: Otros Candidatos | CZ2: Hugo Chávez | DC2: Henrique Capriles | DF2: Otros Candidatos | DK2: Hugo Chávez | DN2: Henrique Capriles | DQ2: Otros Candidatos | DV2: Hugo Chávez | DY2: Henrique Capriles | EB2: Otros Candidatos | EG2: Hugo Chávez | EJ2: Henrique Capriles | EM2: Otros Candidatos | ER2: Hugo Chávez | EU2: Henrique Capriles | EX2: Otros Candidatos | FC2: Hugo Chávez | FF2: Henrique Capriles | FI2: Otros Candidatos | FN2: Hugo Chávez | FQ2: Henrique Capriles | FT2: Otros Candidatos | FY2: Hugo Chávez | GB2: Henrique Capriles | GE2: Otros Candidatos | GJ2: Hugo Chávez | GM2: Henrique Capriles | GP2: Otros Candidatos | GU2: Hugo Chávez | GX2: Henrique Capriles | HA2: Otros Candidatos | HF2: Hugo Chávez | HI2: Henrique Capriles | HL2: Otros Candidatos | HQ2: Hugo Chávez | HT2: Henrique Capriles | HW2: Otros Candidatos | IB2: Hugo Chávez | IE2: Henrique Capriles | IH2: Otros Candidatos | IM2: Hugo Chávez | IP2: Henrique Capriles | IS2: Otros Candidatos | IX2: Hugo Chávez | JA2: Henrique Capriles | JD2: Otros Candidatos | JI2: Hugo Chávez | JL2: Henrique Capriles | JO2: Otros Candidatos | JT2: Hugo Chávez | JW2: Henrique Capriles | JZ2: Otros Candidatos | KE2: Hugo Chávez | KH2: Henrique Capriles | KK2: Otros Candidatos | KP2: Hugo Chávez | KS2: Henrique Capriles | KV2: Otros Candidatos | LA2: Hugo Chávez | LD2: Henrique Capriles | LG2: Otros Candidatos | LL2: Hugo Chávez | LO2: Henrique Capriles | LR2: Otros Candidatos | LW2: Hugo Chávez | LZ2: Henrique Capriles | MC2: Otros Candidatos
B3: =E3/SUM($E$2:$E$4) -> 0.4466627 | C3: Capriles | E3: =SUM(F3:Y3) -> 84.479672 | F3: =SUM(F6,F9,F12,F15,F18,F21,F24,F27,F30,F33,F36,F39,F42,F45,F48,F51,F54,F57,F60,F63,F66,F69,F72,F75) -> 8.6870386 | G3: =SUM(G6,G9,G12,G15,G18,G21,G24,G27,G30,G33,G36,G39,G42,G45,G48,G51,G54,G57,G60,G63,G66,G69,G72,G75) -> 8.2955015 | H3: =SUM(H6,H9,H12,H15,H18,H21,H24,H27,H30,H33,H36,H39,H42,H45,H48,H51,H54,H57,H60,H63,H66,H69,H72,H75) -> 8.4424502 | I3: =SUM(I6,I9,I12,I15,I18,I21,I24,I27,I30,I33,I36,I39,I42,I45,I48,I51,I54,I57,I60,I63,I66,I69,I72,I75) -> 9.9910437 | J3: =SUM(J6,J9,J12,J15,J18,J21,J24,J27,J30,J33,J36,J39,J42,J45,J48,J51,J54,J57,J60,J63,J66,J69,J72,J75) -> 9.5419483 | K3: =SUM(K6,K9,K12,K15,K18,K21,K24,K27,K30,K33,K36,K39,K42,K45,K48,K51,K54,K57,K60,K63,K66,K69,K72,K75) -> 8.7920606 | L3: =SUM(L6,L9,L12,L15,L18,L21,L24,L27,L30,L33,L36,L39,L42,L45,L48,L51,L54,L57,L60,L63,L66,L69,L72,L75) -> 9.8916577 | M3: =SUM(M6,M9,M12,M15,M18,M21,M24,M27,M30,M33,M36,M39,M42,M45,M48,M51,M54,M57,M60,M63,M66,M69,M72,M75) -> 9.2207942 | ... Y3: =SUM(Y6,Y9,Y12,Y15,Y18,Y21,Y24,Y27,Y30,Y33,Y36,Y39,Y42,Y45,Y48,Y51,Y54,Y57,Y60,Y63,Y66,Y69,Y72,Y75) -> 0 | AR3: =AU3/SUM($AU2:$AU4) -> 0.47508224 | AS3: Capriles | AT3: VENEZUELA | AU3: =SUM(AU6,AU9,AU12,AU15,AU18,AU21,AU24,AU27,AU30,AU33,AU36,AU39,AU42,AU45,AU48,AU51,AU54,AU57,AU60,AU63,AU66,AU69,AU72,AU75) -> 47.508224 | AV3: =SUM(AV6,AV9,AV12,AV15,AV18,AV21,AV24,AV27,AV30,AV33,AV36,AV39,AV42,AV45,AV48,AV51,AV54,AV57,AV60,AV63,AV66,AV69,AV72,AV75) -> 46.133798 | AW3: =SUM(AW6,AW9,AW12,AW15,AW18,AW21,AW24,AW27,AW30,AW33,AW36,AW39,AW42,AW45,AW48,AW51,AW54,AW57,AW60,AW63,AW66,AW69,AW72,AW75) -> 43.216322 | AX3: =SUM(AX6,AX9,AX12,AX15,AX18,AX21,AX24,AX27,AX30,AX33,AX36,AX39,AX42,AX45,AX48,AX51,AX54,AX57,AX60,AX63,AX66,AX69,AX72,AX75) -> 44.990202 | AY3: =SUM(AY6,AY9,AY12,AY15,AY18,AY21,AY24,AY27,AY30,AY33,AY36,AY39,AY42,AY45,AY48,AY51,AY54,AY57,AY60,AY63,AY66,AY69,AY72,AY75) -> 49.166763 | AZ3: =SUM(AZ6,AZ9,AZ12,AZ15,AZ18,AZ21,AZ24,AZ27,AZ30,AZ33,AZ36,AZ39,AZ42,AZ45,AZ48,AZ51,AZ54,AZ57,AZ60,AZ63,AZ66,AZ69,AZ72,AZ75) -> 46.940579 | BA3: =SUM(BA6,BA9,BA12,BA15,BA18,BA21,BA24,BA27,BA30,BA33,BA36,BA39,BA42,BA45,BA48,BA51,BA54,BA57,BA60,BA63,BA66,BA69,BA72,BA75) -> 50.04803 | BB3: =SUM(BB6,BB9,BB12,BB15,BB18,BB21,BB24,BB27,BB30,BB33,BB36,BB39,BB42,BB45,BB48,BB51,BB54,BB57,BB60,BB63,BB66,BB69,BB72,BB75) -> 48.58094 | ... BO3: =SUM(BO6,BO9,BO12,BO15,BO18,BO21,BO24,BO27,BO30,BO33,BO36,BO39,BO42,BO45,BO48,BO51,BO54,BO57,BO60,BO63,BO66,BO69,BO72,BO75) -> 0
B4: =E4/SUM($E$2:$E$4) -> 0.012905334 | C4: Otro | E4: =SUM(F4:Y4) -> 2.4408539 | F4: =SUM(F7,F10,F13,F16,F19,F22,F25,F28,F31,F34,F37,F40,F43,F46,F49,F52,F55,F58,F61,F64,F67,F70,F73,F76) -> 0.27483682 | G4: =SUM(G7,G10,G13,G16,G19,G22,G25,G28,G31,G34,G37,G40,G43,G46,G49,G52,G55,G58,G61,G64,G67,G70,G73,G76) -> 0.24563549 | H4: =SUM(H7,H10,H13,H16,H19,H22,H25,H28,H31,H34,H37,H40,H43,H46,H49,H52,H55,H58,H61,H64,H67,H70,H73,H76) -> 0.18834323 | I4: =SUM(I7,I10,I13,I16,I19,I22,I25,I28,I31,I34,I37,I40,I43,I46,I49,I52,I55,I58,I61,I64,I67,I70,I73,I76) -> 0.28704234 | J4: =SUM(J7,J10,J13,J16,J19,J22,J25,J28,J31,J34,J37,J40,J43,J46,J49,J52,J55,J58,J61,J64,J67,J70,J73,J76) -> 0.31539415 | K4: =SUM(K7,K10,K13,K16,K19,K22,K25,K28,K31,K34,K37,K40,K43,K46,K49,K52,K55,K58,K61,K64,K67,K70,K73,K76) -> 0.18727819 | L4: =SUM(L7,L10,L13,L16,L19,L22,L25,L28,L31,L34,L37,L40,L43,L46,L49,L52,L55,L58,L61,L64,L67,L70,L73,L76) -> 0.15047218 | M4: =SUM(M7,M10,M13,M16,M19,M22,M25,M28,M31,M34,M37,M40,M43,M46,M49,M52,M55,M58,M61,M64,M67,M70,M73,M76) -> 0.3540959 | ... Y4: =SUM(Y7,Y10,Y13,Y16,Y19,Y22,Y25,Y28,Y31,Y34,Y37,Y40,Y43,Y46,Y49,Y52,Y55,Y58,Y61,Y64,Y67,Y70,Y73,Y76) -> 0 | AR4: =AU4/SUM($AU2:$AU4) -> 0.015544682 | AS4: Otro | AU4: =SUM(AU7,AU10,AU13,AU16,AU19,AU22,AU25,AU28,AU31,AU34,AU37,AU40,AU43,AU46,AU49,AU52,AU55,AU58,AU61,AU64,AU67,AU70,AU73,AU76) -> 1.5544682 | AV4: =SUM(AV7,AV10,AV13,AV16,AV19,AV22,AV25,AV28,AV31,AV34,AV37,AV40,AV43,AV46,AV49,AV52,AV55,AV58,AV61,AV64,AV67,AV70,AV73,AV76) -> 1.3866408 | AW4: =SUM(AW7,AW10,AW13,AW16,AW19,AW22,AW25,AW28,AW31,AW34,AW37,AW40,AW43,AW46,AW49,AW52,AW55,AW58,AW61,AW64,AW67,AW70,AW73,AW76) -> 1.3029626 | AX4: =SUM(AX7,AX10,AX13,AX16,AX19,AX22,AX25,AX28,AX31,AX34,AX37,AX40,AX43,AX46,AX49,AX52,AX55,AX58,AX61,AX64,AX67,AX70,AX73,AX76) -> 1.2116019 | AY4: =SUM(AY7,AY10,AY13,AY16,AY19,AY22,AY25,AY28,AY31,AY34,AY37,AY40,AY43,AY46,AY49,AY52,AY55,AY58,AY61,AY64,AY67,AY70,AY73,AY76) -> 1.3557404 | AZ4: =SUM(AZ7,AZ10,AZ13,AZ16,AZ19,AZ22,AZ25,AZ28,AZ31,AZ34,AZ37,AZ40,AZ43,AZ46,AZ49,AZ52,AZ55,AZ58,AZ61,AZ64,AZ67,AZ70,AZ73,AZ76) -> 1.7815761 | BA4: =SUM(BA7,BA10,BA13,BA16,BA19,BA22,BA25,BA28,BA31,BA34,BA37,BA40,BA43,BA46,BA49,BA52,BA55,BA58,BA61,BA64,BA67,BA70,BA73,BA76) -> 1.4401939 | BB4: =SUM(BB7,BB10,BB13,BB16,BB19,BB22,BB25,BB28,BB31,BB34,BB37,BB40,BB43,BB46,BB49,BB52,BB55,BB58,BB61,BB64,BB67,BB70,BB73,BB76) -> 1.1739562 | ... BO4: =SUM(BO7,BO10,BO13,BO16,BO19,BO22,BO25,BO28,BO31,BO34,BO37,BO40,BO43,BO46,BO49,BO52,BO55,BO58,BO61,BO64,BO67,BO70,BO73,BO76) -> 0 | BP4: 1 | BQ4: 7:30 | BR4: 8:00 | BS4: =AV2 -> 51.877275 | BT4: =BS4 -> 51.877275 | BU4: =IF((BS4+BV4+BY4)<>0,BT4/(BT4+BW4+BZ4),NA()) -> 0.52191618 | BV4: =AV3 -> 46.133798 | BW4: =BV4 -> 46.133798 | BX4: =IF((BS4+BV4+BY4)<>0,BW4/(BT4+BW4+BZ4),NA()) -> 0.46413339 | BY4: =AV4 -> 1.3866408 | BZ4: =BY4 -> 1.3866408 | CA4: =IF((BS4+BV4+BY4)<>0,BZ4/(BT4+BW4+BZ4),NA()) -> 0.01395043 | CC4: 7:00 | CD4: =$F$5 -> 0.38709677 | CE4: =CD4 -> 0.38709677 | CF4: =IF((CD4+CG4+CJ4)<>0,CE4/(CE4+CH4+CK4),NA()) -> 0.38709677 | CG4: =$F$6 -> 0.61290323 | CH4: =CG4 -> 0.61290323 | CI4: =IF((CD4+CG4+CJ4)<>0,CH4/(CE4+CH4+CK4),NA()) -> 0.61290323 | CJ4: =$F$7 -> 0 | CK4: =CJ4 -> 0 | CL4: =IF((CD4+CG4+CJ4)<>0,CK4/(CE4+CH4+CK4),NA()) -> 0 | CN4: 7:00 | CO4: =$F$8 -> 0.61948413 | CP4: =CO4 -> 0.61948413 | CQ4: =IF((CO4+CR4+CU4)<>0,CP4/(CP4+CS4+CV4),NA()) -> 0.61948413 | CR4: =$F$9 -> 0.37110951 | CS4: =CR4 -> 0.37110951 | CT4: =IF((CO4+CR4+CU4)<>0,CS4/(CP4+CS4+CV4),NA()) -> 0.37110951 | CU4: =$F$10 -> 0.009406357 | CV4: =CU4 -> 0.009406357 | CW4: =IF((CO4+CR4+CU4)<>0,CV4/(CP4+CS4+CV4),NA()) -> 0.009406357 | CY4: 7:00 | CZ4: =$F$11 -> 0.62246852 | DA4: =CZ4 -> 0.62246852 | DB4: =IF((CZ4+DC4+DF4)<>0,DA4/(DA4+DD4+DG4),NA()) -> 0.62246852 | DC4: =$F$12 -> 0.3341173 | DD4: =DC4 -> 0.3341173 | DE4: =IF((CZ4+DC4+DF4)<>0,DD4/(DA4+DD4+DG4),NA()) -> 0.3341173 | DF4: =$F$13 -> 0.043414178 | DG4: =DF4 -> 0.043414178 | DH4: =IF((CZ4+DC4+DF4)<>0,DG4/(DA4+DD4+DG4),NA()) -> 0.043414178 | DJ4: 7:00 | DK4: =$F$14 -> 0.44222325 | DL4: =DK4 -> 0.44222325 | DM4: =IF((DK4+DN4+DQ4)<>0,DL4/(DL4+DO4+DR4),NA()) -> 0.51552035 | DN4: =$F$15 -> 0.41060128 | DO4: =DN4 -> 0.41060128 | DP4: =IF((DK4+DN4+DQ4)<>0,DO4/(DL4+DO4+DR4),NA()) -> 0.47865714 | DQ4: =$F$16 -> 0.0049946657 | DR4: =DQ4 -> 0.0049946657 | DS4: =IF((DK4+DN4+DQ4)<>0,DR4/(DL4+DO4+DR4),NA()) -> 0.0058225156 | DU4: 7:00 | DV4: =$F$17 -> 0.37987841 | DW4: =DV4 -> 0.37987841 | DX4: =IF((DV4+DY4+EB4)<>0,DW4/(DW4+DZ4+EC4),NA()) -> 0.41914825 | DY4: =$F$18 -> 0.52181773 | DZ4: =DY4 -> 0.52181773 | EA4: =IF((DV4+DY4+EB4)<>0,DZ4/(DW4+DZ4+EC4),NA()) -> 0.57576051 | EB4: =$F$19 -> 0.0046142366 | EC4: =EB4 -> 0.0046142366 | ED4: =IF((DV4+DY4+EB4)<>0,EC4/(DW4+DZ4+EC4),NA()) -> 0.0050912322 | EF4: 7:00 | EG4: =$F$20 -> 0.65011673 | EH4: =EG4 -> 0.65011673 | EI4: =IF((EG4+EJ4+EM4)<>0,EH4/(EH4+EK4+EN4),NA()) -> 0.65011673 | EJ4: =$F$21 -> 0.34988327 | EK4: =EJ4 -> 0.34988327 | EL4: =IF((EG4+EJ4+EM4)<>0,EK4/(EH4+EK4+EN4),NA()) -> 0.34988327 | EM4: =$F$22 -> 0 | EN4: =EM4 -> 0 | EO4: =IF((EG4+EJ4+EM4)<>0,EN4/(EH4+EK4+EN4),NA()) -> 0 | EQ4: 7:00 | ER4: =$F$23 -> 0.18344 | ES4: =ER4 -> 0.18344 | ET4: =IF((ER4+EU4+EX4)<>0,ES4/(ES4+EV4+EY4),NA()) -> 0.65433184 | EU4: =$F$24 -> 0.092403544 | EV4: =EU4 -> 0.092403544 | EW4: =IF((ER4+EU4+EX4)<>0,EV4/(ES4+EV4+EY4),NA()) -> 0.32960412 | EX4: =$F$25 -> 0.0045035052 | EY4: =EX4 -> 0.0045035052 | EZ4: =IF((ER4+EU4+EX4)<>0,EY4/(ES4+EV4+EY4),NA()) -> 0.016064036 | FB4: 7:00 | FC4: =$F$26 -> 0.11113275 | FD4: =FC4 -> 0.11113275 | FE4: =IF((FC4+FF4+FI4)<>0,FD4/(FD4+FG4+FJ4),NA()) -> 0.21052632 | FF4: =$F$27 -> 0.41674782 | FG4: =FF4 -> 0.41674782 | FH4: =IF((FC4+FF4+FI4)<>0,FG4/(FD4+FG4+FJ4),NA()) -> 0.78947368 | FI4: =$F$28 -> 0 | FJ4: =FI4 -> 0 | FK4: =IF((FC4+FF4+FI4)<>0,FJ4/(FD4+FG4+FJ4),NA()) -> 0 | FM4: 7:00 | FN4: =$F$29 -> 0 | FO4: =FN4 -> 0 | FP4: =IF((FN4+FQ4+FT4)<>0,FO4/(FO4+FR4+FU4),NA()) -> #N/A | FQ4: =$F$30 -> 0 | FR4: =FQ4 -> 0 | FS4: =IF((FN4+FQ4+FT4)<>0,FR4/(FO4+FR4+FU4),NA()) -> #N/A | FT4: =$F$31 -> 0 | FU4: =FT4 -> 0 | FV4: =IF((FN4+FQ4+FT4)<>0,FU4/(FO4+FR4+FU4),NA()) -> #N/A | FX4: 7:00 | FY4: =$F$32 -> 0.27799603 | FZ4: =FY4 -> 0.27799603 | GA4: =IF((FY4+GB4+GE4)<>0,FZ4/(FZ4+GC4+GF4),NA()) -> 0.4035117 | GB4: =$F$33 -> 0.38705623 | GC4: =GB4 -> 0.38705623 | GD4: =IF((FY4+GB4+GE4)<>0,GC4/(FZ4+GC4+GF4),NA()) -> 0.56181277 | GE4: =$F$34 -> 0.02388942 | GF4: =GE4 -> 0.02388942 | GG4: =IF((FY4+GB4+GE4)<>0,GF4/(FZ4+GC4+GF4),NA()) -> 0.034675534 | GI4: 7:00 | GJ4: =$F$35 -> 0.88318574 | GK4: =GJ4 -> 0.88318574 | GL4: =IF((GJ4+GM4+GP4)<>0,GK4/(GK4+GN4+GQ4),NA()) -> 0.88318574 | GM4: =$F$36 -> 0.11681426 | GN4: =GM4 -> 0.11681426 | GO4: =IF((GJ4+GM4+GP4)<>0,GN4/(GK4+GN4+GQ4),NA()) -> 0.11681426 | GP4: =$F$37 -> 0 | GQ4: =GP4 -> 0 | GR4: =IF((GJ4+GM4+GP4)<>0,GQ4/(GK4+GN4+GQ4),NA()) -> 0 | GT4: 7:00 | GU4: =$F$38 -> 0.46112175 | GV4: =GU4 -> 0.46112175 | GW4: =IF((GU4+GX4+HA4)<>0,GV4/(GV4+GY4+HB4),NA()) -> 0.61195183 | GX4: =$F$39 -> 0.27971647 | GY4: =GX4 -> 0.27971647 | GZ4: =IF((GU4+GX4+HA4)<>0,GY4/(GV4+GY4+HB4),NA()) -> 0.37121001 | HA4: =$F$40 -> 0.012687996 | HB4: =HA4 -> 0.012687996 | HC4: =IF((GU4+GX4+HA4)<>0,HB4/(GV4+GY4+HB4),NA()) -> 0.016838161 | HE4: 7:00 | HF4: =$F$41 -> 0.47995167 | HG4: =HF4 -> 0.47995167 | HH4: =IF((HF4+HI4+HL4)<>0,HG4/(HG4+HJ4+HM4),NA()) -> 0.47995167 | HI4: =$F$42 -> 0.51943647 | HJ4: =HI4 -> 0.51943647 | HK4: =IF((HF4+HI4+HL4)<>0,HJ4/(HG4+HJ4+HM4),NA()) -> 0.51943647 | HL4: =$F$43 -> 0.0006118585 | HM4: =HL4 -> 0.0006118585 | HN4: =IF((HF4+HI4+HL4)<>0,HM4/(HG4+HJ4+HM4),NA()) -> 0.0006118585 | HP4: 7:00 | HQ4: =$F$44 -> 0.61440785 | HR4: =HQ4 -> 0.61440785 | HS4: =IF((HQ4+HT4+HW4)<>0,HR4/(HR4+HU4+HX4),NA()) -> 0.61440785 | HT4: =$F$45 -> 0.37147287 | HU4: =HT4 -> 0.37147287 | HV4: =IF((HQ4+HT4+HW4)<>0,HU4/(HR4+HU4+HX4),NA()) -> 0.37147287 | HW4: =$F$46 -> 0.014119278 | HX4: =HW4 -> 0.014119278 | HY4: =IF((HQ4+HT4+HW4)<>0,HX4/(HR4+HU4+HX4),NA()) -> 0.014119278 | IA4: 7:00 | IB4: =$F$47 -> 0.31387899 | IC4: =IB4 -> 0.31387899 | ID4: =IF((IB4+IE4+IH4)<>0,IC4/(IC4+IF4+II4),NA()) -> 0.37598951 | IE4: =$F$48 -> 0.49505513 | IF4: =IE4 -> 0.49505513 | IG4: =IF((IB4+IE4+IH4)<>0,IF4/(IC4+IF4+II4),NA()) -> 0.59301686 | IH4: =$F$49 -> 0.025873724 | II4: =IH4 -> 0.025873724 | IJ4: =IF((IB4+IE4+IH4)<>0,II4/(IC4+IF4+II4),NA()) -> 0.030993628 | IL4: 7:00 | IM4: =$F$50 -> 0.4115442 | IN4: =IM4 -> 0.4115442 | IO4: =IF((IM4+IP4+IS4)<>0,IN4/(IN4+IQ4+IT4),NA()) -> 0.4115442 | IP4: =$F$51 -> 0.58334281 | IQ4: =IP4 -> 0.58334281 | IR4: =IF((IM4+IP4+IS4)<>0,IQ4/(IN4+IQ4+IT4),NA()) -> 0.58334281 | IS4: =$F$52 -> 0.0051129924 | IT4: =IS4 -> 0.0051129924 | IU4: =IF((IM4+IP4+IS4)<>0,IT4/(IN4+IQ4+IT4),NA()) -> 0.0051129924 | IW4: 7:00 | IX4: =$F$53 -> 0.3717816 | IY4: =IX4 -> 0.3717816 | IZ4: =IF((IX4+JA4+JD4)<>0,IY4/(IY4+JB4+JE4),NA()) -> 0.47250724 | JA4: =$F$54 -> 0.33451758 | JB4: =JA4 -> 0.33451758 | JC4: =IF((IX4+JA4+JD4)<>0,JB4/(IY4+JB4+JE4),NA()) -> 0.42514739 | JD4: =$F$55 -> 0.080528137 | JE4: =JD4 -> 0.080528137 | JF4: =IF((IX4+JA4+JD4)<>0,JE4/(IY4+JB4+JE4),NA()) -> 0.10234538 | JH4: 7:00 | JI4: =$F$56 -> 0.30008952 | JJ4: =JI4 -> 0.30008952 | JK4: =IF((JI4+JL4+JO4)<>0,JJ4/(JJ4+JM4+JP4),NA()) -> 0.57579439 | JL4: =$F$57 -> 0.21774336 | JM4: =JL4 -> 0.21774336 | JN4: =IF((JI4+JL4+JO4)<>0,JM4/(JJ4+JM4+JP4),NA()) -> 0.41779335 | JO4: =$F$58 -> 0.0033419073 | JP4: =JO4 -> 0.0033419073 | JQ4: =IF((JI4+JL4+JO4)<>0,JP4/(JJ4+JM4+JP4),NA()) -> 0.0064122583 | JS4: 7:00 | JT4: =$F$59 -> 0.42283927 | JU4: =JT4 -> 0.42283927 | JV4: =IF((JT4+JW4+JZ4)<>0,JU4/(JU4+JX4+KA4),NA()) -> 0.50428591 | JW4: =$F$60 -> 0.40702442 | JX4: =JW4 -> 0.40702442 | JY4: =IF((JT4+JW4+JZ4)<>0,JX4/(JU4+JX4+KA4),NA()) -> 0.48542482 | JZ4: =$F$61 -> 0.0086274643 | KA4: =JZ4 -> 0.0086274643 | KB4: =IF((JT4+JW4+JZ4)<>0,KA4/(JU4+JX4+KA4),NA()) -> 0.010289273 | KD4: 7:00 | KE4: =$F$62 -> 0.34921836 | KF4: =KE4 -> 0.34921836 | KG4: =IF((KE4+KH4+KK4)<>0,KF4/(KF4+KI4+KL4),NA()) -> 0.37588199 | KH4: =$F$63 -> 0.56833643 | KI4: =KH4 -> 0.56833643 | KJ4: =IF((KE4+KH4+KK4)<>0,KI4/(KF4+KI4+KL4),NA()) -> 0.61173023 | KK4: =$F$64 -> 0.011509037 | KL4: =KK4 -> 0.011509037 | KM4: =IF((KE4+KH4+KK4)<>0,KL4/(KF4+KI4+KL4),NA()) -> 0.012387778 | KO4: 7:00 | KP4: =$F$65 -> 0.61733055 | KQ4: =KP4 -> 0.61733055 | KR4: =IF((KP4+KS4+KV4)<>0,KQ4/(KQ4+KT4+KW4),NA()) -> 0.70885838 | KS4: =$F$66 -> 0.24273341 | KT4: =KS4 -> 0.24273341 | KU4: =IF((KP4+KS4+KV4)<>0,KT4/(KQ4+KT4+KW4),NA()) -> 0.27872201 | KV4: =$F$67 -> 0.010815991 | KW4: =KV4 -> 0.010815991 | KX4: =IF((KP4+KS4+KV4)<>0,KW4/(KQ4+KT4+KW4),NA()) -> 0.012419612 | KZ4: 7:00 | LA4: =$F$68 -> 0.34806021 | LB4: =LA4 -> 0.34806021 | LC4: =IF((LA4+LD4+LG4)<>0,LB4/(LB4+LE4+LH4),NA()) -> 0.68965517 | LD4: =$F$69 -> 0.15662709 | LE4: =LD4 -> 0.15662709 | LF4: =IF((LA4+LD4+LG4)<>0,LE4/(LB4+LE4+LH4),NA()) -> 0.31034483 | LG4: =$F$70 -> 0 | LH4: =LG4 -> 0 | LI4: =IF((LA4+LD4+LG4)<>0,LH4/(LB4+LE4+LH4),NA()) -> 0 | LK4: 7:00 | LL4: =$F$71 -> 0.54784385 | LM4: =LL4 -> 0.54784385 | LN4: =IF((LL4+LO4+LR4)<>0,LM4/(LM4+LP4+LS4),NA()) -> 0.54784385 | LO4: =$F$72 -> 0.44272206 | LP4: =LO4 -> 0.44272206 | LQ4: =IF((LL4+LO4+LR4)<>0,LP4/(LM4+LP4+LS4),NA()) -> 0.44272206 | LR4: =$F$73 -> 0.0094340948 | LS4: =LR4 -> 0.0094340948 | LT4: =IF((LL4+LO4+LR4)<>0,LS4/(LM4+LP4+LS4),NA()) -> 0.0094340948 | LV4: 7:00 | LW4: =$F$74 -> 0.43453075 | LX4: =LW4 -> 0.43453075 | LY4: =IF((LW4+LZ4+MC4)<>0,LX4/(LX4+MA4+MD4),NA()) -> 0.48783172 | LZ4: =$F$75 -> 0.4548563 | MA4: =LZ4 -> 0.4548563 | MB4: =IF((LW4+LZ4+MC4)<>0,MA4/(LX4+MA4+MD4),NA()) -> 0.51065047 | MC4: =$F$76 -> 0.001351976 | MD4: =MC4 -> 0.001351976 | ME4: =IF((LW4+LZ4+MC4)<>0,MD4/(LX4+MA4+MD4),NA()) -> 0.0015178138
B5: =E5/SUM($E$5:$E$7) -> 0.58762887 | C5: Chavez | E5: =CORE!E6 -> 0.58762887 | F5: =CORE!F6 -> 0.38709677 | G5: =CORE!G6 -> 0.66666667 | H5: =CORE!H6 -> 0 | I5: =CORE!I6 -> 0.47058824 | J5: =CORE!J6 -> 0.51428571 | K5: =CORE!K6 -> 1 | L5: =CORE!L6 -> 0 | ... Y5: =CORE!Y6 -> 0 | AQ5: 0.51210801 | AR5: =AU5/SUM($AU5:$AU7) -> 0.58762887 | AS5: Chavez | AU5: =IF((E5+E6+E7)=0,1,E5/(E5+E6+E7)*$AQ5) -> 0.30092945 | AV5: =IF((F5+F6+F7)=0,0,F5/(F5+F6+F7)*$AQ5) -> 0.19823536 | AW5: =IF((G5+G6+G7)=0,0,G5/(G5+G6+G7)*$AQ5) -> 0.34140534 | AX5: =IF((H5+H6+H7)=0,0,H5/(H5+H6+H7)*$AQ5) -> 0 | AY5: =IF((I5+I6+I7)=0,0,I5/(I5+I6+I7)*$AQ5) -> 0.24099201 | AZ5: =IF((J5+J6+J7)=0,0,J5/(J5+J6+J7)*$AQ5) -> 0.26336983 | BA5: =IF((K5+K6+K7)=0,0,K5/(K5+K6+K7)*$AQ5) -> 0.51210801 | BB5: =IF((L5+L6+L7)=0,0,L5/(L5+L6+L7)*$AQ5) -> 0 | BC5: =IF((M5+M6+M7)=0,0,M5/(M5+M6+M7)*$AQ5) -> 0.38408101 | ... BO5: =IF((Y5+Y6+Y7)=0,0,Y5/(Y5+Y6+Y7)*$AQ5) -> 0 | BP5: 2 | BQ5: 8:00 | BR5: 8:30 | BS5: =AW2 -> 54.878429 | BT5: =BT4+BS5 -> 106.7557 | BU5: =IF((BS5+BV5+BY5)<>0,BT5/(BT5+BW5+BZ5),NA()) -> 0.53701287 | BV5: =AW3 -> 43.216322 | BW5: =BW4+BV5 -> 89.35012 | BX5: =IF((BS5+BV5+BY5)<>0,BW5/(BT5+BW5+BZ5),NA()) -> 0.44945762 | BY5: =AW4 -> 1.3029626 | BZ5: =BZ4+BY5 -> 2.6896034 | CA5: =IF((BS5+BV5+BY5)<>0,BZ5/(BT5+BW5+BZ5),NA()) -> 0.013529504 | CC5: 7:30 | CD5: =$G$5 -> 0.66666667 | CE5: =CE4+CD5 -> 1.0537634 | CF5: =IF((CD5+CG5+CJ5)<>0,CE5/(CE5+CH5+CK5),NA()) -> 0.52688172 | CG5: =$G$6 -> 0.33333333 | CH5: =CH4+CG5 -> 0.94623656 | CI5: =IF((CD5+CG5+CJ5)<>0,CH5/(CE5+CH5+CK5),NA()) -> 0.47311828 | CJ5: =$G$7 -> 0 | CK5: =CK4+CJ5 -> 0 | CL5: =IF((CD5+CG5+CJ5)<>0,CK5/(CE5+CH5+CK5),NA()) -> 0 | CN5: 7:30 | CO5: =$G$8 -> 0.59614116 | CP5: =CP4+CO5 -> 1.2156253 | CQ5: =IF((CO5+CR5+CU5)<>0,CP5/(CP5+CS5+CV5),NA()) -> 0.66496469 | CR5: =$G$9 -> 0.22858934 | CS5: =CS4+CR5 -> 0.59969885 | CT5: =IF((CO5+CR5+CU5)<>0,CS5/(CP5+CS5+CV5),NA()) -> 0.32804398 | CU5: =$G$10 -> 0.0033745258 | CV5: =CV4+CU5 -> 0.012780883 | CW5: =IF((CO5+CR5+CU5)<>0,CV5/(CP5+CS5+CV5),NA()) -> 0.0069913285 | CY5: 7:30 | CZ5: =$G$11 -> 0.53585642 | DA5: =DA4+CZ5 -> 1.1583249 | DB5: =IF((CZ5+DC5+DF5)<>0,DA5/(DA5+DD5+DG5),NA()) -> 0.62891753 | DC5: =$G$12 -> 0.27289609 | DD5: =DD4+DC5 -> 0.60701339 | DE5: =IF((CZ5+DC5+DF5)<>0,DD5/(DA5+DD5+DG5),NA()) -> 0.32958054 | DF5: =$G$13 -> 0.033023054 | DG5: =DG4+DF5 -> 0.076437232 | DH5: =IF((CZ5+DC5+DF5)<>0,DG5/(DA5+DD5+DG5),NA()) -> 0.041501925 | DJ5: 7:30 | DK5: =$G$14 -> 0.56941577 | DL5: =DL4+DK5 -> 1.011639 | DM5: =IF((DK5+DN5+DQ5)<>0,DL5/(DL5+DO5+DR5),NA()) -> 0.5445304 | DN5: =$G$15 -> 0.4026892 | DO5: =DO4+DN5 -> 0.81329048 | DP5: =IF((DK5+DN5+DQ5)<>0,DO5/(DL5+DO5+DR5),NA()) -> 0.43776622 | DQ5: =$G$16 -> 0.027895023 | DR5: =DR4+DQ5 -> 0.032889689 | DS5: =IF((DK5+DN5+DQ5)<>0,DR5/(DL5+DO5+DR5),NA()) -> 0.017703385 | DU5: 7:30 | DV5: =$G$17 -> 0.34406488 | DW5: =DW4+DV5 -> 0.72394329 | DX5: =IF((DV5+DY5+EB5)<>0,DW5/(DW5+DZ5+EC5),NA()) -> 0.39939038 | DY5: =$G$18 -> 0.56224551 | DZ5: =DZ4+DY5 -> 1.0840632 | EA5: =IF((DV5+DY5+EB5)<>0,DZ5/(DW5+DZ5+EC5),NA()) -> 0.59806401 | EB5: =$G$19 -> 0 | EC5: =EC4+EB5 -> 0.0046142366 | ED5: =IF((DV5+DY5+EB5)<>0,EC5/(DW5+DZ5+EC5),NA()) -> 0.0025456161 | EF5: 7:30 | EG5: =$G$20 -> 0.48896585 | EH5: =EH4+EG5 -> 1.1390826 | EI5: =IF((EG5+EJ5+EM5)<>0,EH5/(EH5+EK5+EN5),NA()) -> 0.56954129 | EJ5: =$G$21 -> 0.49812942 | EK5: =EK4+EJ5 -> 0.84801269 | EL5: =IF((EG5+EJ5+EM5)<>0,EK5/(EH5+EK5+EN5),NA()) -> 0.42400634 | EM5: =$G$22 -> 0.012904734 | EN5: =EN4+EM5 -> 0.012904734 | EO5: =IF((EG5+EJ5+EM5)<>0,EN5/(EH5+EK5+EN5),NA()) -> 0.0064523672 | EQ5: 7:30 | ER5: =$G$23 -> 0.43435946 | ES5: =ES4+ER5 -> 0.61779946 | ET5: =IF((ER5+EU5+EX5)<>0,ES5/(ES5+EV5+EY5),NA()) -> 0.58768435 | EU5: =$G$24 -> 0.30796706 | EV5: =EV4+EU5 -> 0.4003706 | EW5: =IF((ER5+EU5+EX5)<>0,EV5/(ES5+EV5+EY5),NA()) -> 0.38085423 | EX5: =$G$25 -> 0.028570116 | EY5: =EY4+EX5 -> 0.033073621 | EZ5: =IF((ER5+EU5+EX5)<>0,EY5/(ES5+EV5+EY5),NA()) -> 0.031461422 | FB5: 7:30 | FC5: =$G$26 -> 0.51906524 | FD5: =FD4+FC5 -> 0.63019799 | FE5: =IF((FC5+FF5+FI5)<>0,FD5/(FD5+FG5+FJ5),NA()) -> 0.41246548 | FF5: =$G$27 -> 0.45454073 | FG5: =FG4+FF5 -> 0.87128855 | FH5: =IF((FC5+FF5+FI5)<>0,FG5/(FD5+FG5+FJ5),NA()) -> 0.57025959 | FI5: =$G$28 -> 0.026394028 | FJ5: =FJ4+FI5 -> 0.026394028 | FK5: =IF((FC5+FF5+FI5)<>0,FJ5/(FD5+FG5+FJ5),NA()) -> 0.017274929 | FM5: 7:30 | FN5: =$G$29 -> 0 | FO5: =FO4+FN5 -> 0 | FP5: =IF((FN5+FQ5+FT5)<>0,FO5/(FO5+FR5+FU5),NA()) -> #N/A | FQ5: =$G$30 -> 0 | FR5: =FR4+FQ5 -> 0 | FS5: =IF((FN5+FQ5+FT5)<>0,FR5/(FO5+FR5+FU5),NA()) -> #N/A | FT5: =$G$31 -> 0 | FU5: =FU4+FT5 -> 0 | FV5: =IF((FN5+FQ5+FT5)<>0,FU5/(FO5+FR5+FU5),NA()) -> #N/A | FX5: 7:30 | FY5: =$G$32 -> 0.34662794 | FZ5: =FZ4+FY5 -> 0.62462397 | GA5: =IF((FY5+GB5+GE5)<>0,FZ5/(FZ5+GC5+GF5),NA()) -> 0.45806477 | GB5: =$G$33 -> 0.30710299 | GC5: =GC4+GB5 -> 0.69415922 | GD5: =IF((FY5+GB5+GE5)<>0,GC5/(FZ5+GC5+GF5),NA()) -> 0.50905809 | GE5: =$G$34 -> 0.020942334 | GF5: =GF4+GE5 -> 0.044831755 | GG5: =IF((FY5+GB5+GE5)<>0,GF5/(FZ5+GC5+GF5),NA()) -> 0.032877136 | GI5: 7:30 | GJ5: =$G$35 -> 0.35286956 | GK5: =GK4+GJ5 -> 1.2360553 | GL5: =IF((GJ5+GM5+GP5)<>0,GK5/(GK5+GN5+GQ5),NA()) -> 0.83743401 | GM5: =$G$36 -> 0.12313366 | GN5: =GN4+GM5 -> 0.23994792 | GO5: =IF((GJ5+GM5+GP5)<>0,GN5/(GK5+GN5+GQ5),NA()) -> 0.16256599 | GP5: =$G$37 -> 0 | GQ5: =GQ4+GP5 -> 0 | GR5: =IF((GJ5+GM5+GP5)<>0,GQ5/(GK5+GN5+GQ5),NA()) -> 0 | GT5: 7:30 | GU5: =$G$38 -> 0.14747707 | GV5: =GV4+GU5 -> 0.60859882 | GW5: =IF((GU5+GX5+HA5)<>0,GV5/(GV5+GY5+HB5),NA()) -> 0.67546792 | GX5: =$G$39 -> 0 | GY5: =GY4+GX5 -> 0.27971647 | GZ5: =IF((GU5+GX5+HA5)<>0,GY5/(GV5+GY5+HB5),NA()) -> 0.31045 | HA5: =$G$40 -> 0 | HB5: =HB4+HA5 -> 0.012687996 | HC5: =IF((GU5+GX5+HA5)<>0,HB5/(GV5+GY5+HB5),NA()) -> 0.014082075 | HE5: 7:30 | HF5: =$G$41 -> 0.52775906 | HG5: =HG4+HF5 -> 1.0077107 | HH5: =IF((HF5+HI5+HL5)<>0,HG5/(HG5+HJ5+HM5),NA()) -> 0.50385536 | HI5: =$G$42 -> 0.47224094 | HJ5: =HJ4+HI5 -> 0.99167742 | HK5: =IF((HF5+HI5+HL5)<>0,HJ5/(HG5+HJ5+HM5),NA()) -> 0.49583871 | HL5: =$G$43 -> 0 | HM5: =HM4+HL5 -> 0.0006118585 | HN5: =IF((HF5+HI5+HL5)<>0,HM5/(HG5+HJ5+HM5),NA()) -> 0.00030592925 | HP5: 7:30 | HQ5: =$G$44 -> 0.54748456 | HR5: =HR4+HQ5 -> 1.1618924 | HS5: =IF((HQ5+HT5+HW5)<>0,HR5/(HR5+HU5+HX5),NA()) -> 0.58094621 | HT5: =$G$45 -> 0.44180715 | HU5: =HU4+HT5 -> 0.81328003 | HV5: =IF((HQ5+HT5+HW5)<>0,HU5/(HR5+HU5+HX5),NA()) -> 0.40664001 | HW5: =$G$46 -> 0.010708283 | HX5: =HX4+HW5 -> 0.02482756 | HY5: =IF((HQ5+HT5+HW5)<>0,HX5/(HR5+HU5+HX5),NA()) -> 0.01241378 | IA5: 7:30 | IB5: =$G$47 -> 0.23928008 | IC5: =IC4+IB5 -> 0.55315907 | ID5: =IF((IB5+IE5+IH5)<>0,IC5/(IC5+IF5+II5),NA()) -> 0.34641329 | IE5: =$G$48 -> 0.52174818 | IF5: =IF4+IE5 -> 1.0168033 | IG5: =IF((IB5+IE5+IH5)<>0,IF5/(IC5+IF5+II5),NA()) -> 0.63676832 | IH5: =$G$49 -> 0.00098218877 | II5: =II4+IH5 -> 0.026855913 | IJ5: =IF((IB5+IE5+IH5)<>0,II5/(IC5+IF5+II5),NA()) -> 0.01681839 | IL5: 7:30 | IM5: =$G$50 -> 0.27716266 | IN5: =IN4+IM5 -> 0.68870686 | IO5: =IF((IM5+IP5+IS5)<>0,IN5/(IN5+IQ5+IT5),NA()) -> 0.34435343 | IP5: =$G$51 -> 0.72028085 | IQ5: =IQ4+IP5 -> 1.3036237 | IR5: =IF((IM5+IP5+IS5)<>0,IQ5/(IN5+IQ5+IT5),NA()) -> 0.65181183 | IS5: =$G$52 -> 0.0025564962 | IT5: =IT4+IS5 -> 0.0076694886 | IU5: =IF((IM5+IP5+IS5)<>0,IT5/(IN5+IQ5+IT5),NA()) -> 0.0038347443 | IW5: 7:30 | IX5: =$G$53 -> 0.6727196 | IY5: =IY4+IX5 -> 1.0445012 | IZ5: =IF((IX5+JA5+JD5)<>0,IY5/(IY5+JB5+JE5),NA()) -> 0.58455632 | JA5: =$G$54 -> 0.28701633 | JB5: =JB4+JA5 -> 0.62153391 | JC5: =IF((IX5+JA5+JD5)<>0,JB5/(IY5+JB5+JE5),NA()) -> 0.34784218 | JD5: =$G$55 -> 0.040264068 | JE5: =JE4+JD5 -> 0.12079221 | JF5: =IF((IX5+JA5+JD5)<>0,JE5/(IY5+JB5+JE5),NA()) -> 0.067601499 | JH5: 7:30 | JI5: =$G$56 -> 0.87737386 | JJ5: =JJ4+JI5 -> 1.1774634 | JK5: =IF((JI5+JL5+JO5)<>0,JJ5/(JJ5+JM5+JP5),NA()) -> 0.77404871 | JL5: =$G$57 -> 0.11598215 | JM5: =JM4+JL5 -> 0.33372551 | JN5: =IF((JI5+JL5+JO5)<>0,JM5/(JJ5+JM5+JP5),NA()) -> 0.2193867 | JO5: =$G$58 -> 0.0066439922 | JP5: =JP4+JO5 -> 0.0099858996 | JQ5: =IF((JI5+JL5+JO5)<>0,JP5/(JJ5+JM5+JP5),NA()) -> 0.0065645971 | JS5: 7:30 | JT5: =$G$59 -> 0.54518466 | JU5: =JU4+JT5 -> 0.96802393 | JV5: =IF((JT5+JW5+JZ5)<>0,JU5/(JU5+JX5+KA5),NA()) -> 0.55328842 | JW5: =$G$60 -> 0.35886886 | JX5: =JX4+JW5 -> 0.76589327 | JY5: =IF((JT5+JW5+JZ5)<>0,JX5/(JU5+JX5+KA5),NA()) -> 0.43775764 | JZ5: =$G$61 -> 0.0070381946 | KA5: =KA4+JZ5 -> 0.015665659 | KB5: =IF((JT5+JW5+JZ5)<>0,KA5/(JU5+JX5+KA5),NA()) -> 0.0089539394 | KD5: 7:30 | KE5: =$G$62 -> 0.22742758 | KF5: =KF4+KE5 -> 0.57664594 | KG5: =IF((KE5+KH5+KK5)<>0,KF5/(KF5+KI5+KL5),NA()) -> 0.31789106 | KH5: =$G$63 -> 0.64516658 | KI5: =KI4+KH5 -> 1.213503 | KJ5: =IF((KE5+KH5+KK5)<>0,KI5/(KF5+KI5+KL5),NA()) -> 0.66897506 | KK5: =$G$64 -> 0.012315473 | KL5: =KL4+KK5 -> 0.023824509 | KM5: =IF((KE5+KH5+KK5)<>0,KL5/(KF5+KI5+KL5),NA()) -> 0.01313388 | KO5: 7:30 | KP5: =$G$65 -> 0.66751284 | KQ5: =KQ4+KP5 -> 1.2848434 | KR5: =IF((KP5+KS5+KV5)<>0,KQ5/(KQ5+KT5+KW5),NA()) -> 0.68675886 | KS5: =$G$66 -> 0.33248716 | KT5: =KT4+KS5 -> 0.57522057 | KU5: =IF((KP5+KS5+KV5)<>0,KT5/(KQ5+KT5+KW5),NA()) -> 0.30745991 | KV5: =$G$67 -> 0 | KW5: =KW4+KV5 -> 0.010815991 | KX5: =IF((KP5+KS5+KV5)<>0,KW5/(KQ5+KT5+KW5),NA()) -> 0.0057812321 | KZ5: 7:30 | LA5: =$G$68 -> 0.44780004 | LB5: =LB4+LA5 -> 0.79586025 | LC5: =IF((LA5+LD5+LG5)<>0,LB5/(LB5+LE5+LH5),NA()) -> 0.64042608 | LD5: =$G$69 -> 0.29021696 | LE5: =LE4+LD5 -> 0.44684406 | LF5: =IF((LA5+LD5+LG5)<>0,LE5/(LB5+LE5+LH5),NA()) -> 0.35957392 | LG5: =$G$70 -> 0 | LH5: =LH4+LG5 -> 0 | LI5: =IF((LA5+LD5+LG5)<>0,LH5/(LB5+LE5+LH5),NA()) -> 0 | LK5: 7:30 | LL5: =$G$71 -> 0.49452775 | LM5: =LM4+LL5 -> 1.0423716 | LN5: =IF((LL5+LO5+LR5)<>0,LM5/(LM5+LP5+LS5),NA()) -> 0.59434668 | LO5: =$G$72 -> 0.25928302 | LP5: =LP4+LO5 -> 0.70200507 | LQ5: =IF((LL5+LO5+LR5)<>0,LP5/(LM5+LP5+LS5),NA()) -> 0.40027413 | LR5: =$G$73 -> 0 | LS5: =LS4+LR5 -> 0.0094340948 | LT5: =IF((LL5+LO5+LR5)<>0,LS5/(LM5+LP5+LS5),NA()) -> 0.0053791977 | LV5: 7:30 | LW5: =$G$74 -> 0.60372224 | LX5: =LX4+LW5 -> 1.038253 | LY5: =IF((LW5+LZ5+MC5)<>0,LX5/(LX5+MA5+MD5),NA()) -> 0.5563281 | LZ5: =$G$75 -> 0.35977594 | MA5: =MA4+LZ5 -> 0.81463224 | MB5: =IF((LW5+LZ5+MC5)<>0,MA5/(LX5+MA5+MD5),NA()) -> 0.43650518 | MC5: =$G$76 -> 0.012022982 | MD5: =MD4+MC5 -> 0.013374958 | ME5: =IF((LW5+LZ5+MC5)<>0,MD5/(LX5+MA5+MD5),NA()) -> 0.0071667168
